Workbook

Sheet Dashboard
B1: ="Paid Media Spend "&Settings!$C$12&" – Year Overview" -> Paid Media Spend 2026 – Year Overview | P1: Helper cells for formatting – don't edit
B2: ="Platform data up to "&TEXT(Settings!$C$5,"d mmm yyyy")&" · amounts in "&Settings!$C$6&" · Google converted from EUR at "&TEXT(Settings!$B$41,"0.0000")&" · Meta, Google Ads and ChatGPT Ads" -> Platform data up to 30 Sep 2026 · amounts in USD · Google converted from EUR at 1.1177 · Meta, Google Ads and ChatGPT Ads | P2: =Calc!C9 -> 0.74794521
B3: ="Budget: "&Settings!$C$9 -> Budget: Confirmed by Tereza on 13 Oct 2026: $300k for 2026 (originally $350k). We can go up to $320k, ideally not more. | P3: =Calc!C42-Calc!C27 -> 3058.3922
B5: ="BUDGET "&Settings!$C$12 -> BUDGET 2026 | D5: ="SPENT SO FAR" -> SPENT SO FAR | F5: ="LEFT IN THE BUDGET" -> LEFT IN THE BUDGET | H5: ="LEFT UP TO THE MAXIMUM" -> LEFT UP TO THE MAXIMUM | J5: ="CURRENT PACE PER WEEK" -> CURRENT PACE PER WEEK | L5: ="FORECAST YEAR-END" -> FORECAST YEAR-END
B6: =IF(Settings!$C$6="USD","$","€")&TEXT(Calc!C27,"#,##0") -> $300,000 | D6: =IF(Settings!$C$6="USD","$","€")&TEXT(Calc!C30,"#,##0") -> $278,601 | F6: =IF(Calc!C31<0,"–"&IF(Settings!$C$6="USD","$","€")&TEXT(-Calc!C31,"#,##0"),IF(Settings!$C$6="USD","$","€")&TEXT(Calc!C31,"#,##0")) -> $21,399 | H6: =IF(Calc!C32<0,"–"&IF(Settings!$C$6="USD","$","€")&TEXT(-Calc!C32,"#,##0"),IF(Settings!$C$6="USD","$","€")&TEXT(Calc!C32,"#,##0")) -> $41,399 | J6: =IF(Settings!$C$6="USD","$","€")&TEXT(Calc!C39,"#,##0") -> $1,861 | L6: =IF(Settings!$C$6="USD","$","€")&TEXT(Calc!C42,"#,##0") -> $303,058
B7: ="Maximum "&IF(Settings!$C$6="USD","$","€")&TEXT(Calc!C28,"#,##0")&" · originally "&IF(Settings!$C$6="USD","$","€")&TEXT(Calc!C29,"#,##0") -> Maximum $320,000 · originally $350,000 | D7: =TEXT(Calc!C33,"0%")&" of budget · "&TEXT(Calc!C9,"0%")&" of the year gone" -> 93% of budget · 75% of the year gone | F7: =IF(Calc!C31<0,"Budget already used up","≈ "&IF(Settings!$C$6="USD","$","€")&TEXT(Calc!C43,"#,##0")&" a week until "&TEXT(Calc!C5,"d mmm")) -> ≈ $1,628 a week until 31 Dec | H7: =IF(Calc!C32<0,"Maximum already passed","≈ "&IF(Settings!$C$6="USD","$","€")&TEXT(Calc!C44,"#,##0")&" a week until "&TEXT(Calc!C5,"d mmm")) -> ≈ $3,150 a week until 31 Dec | J7: =IF(Calc!C37>0,"Platforms, last 3 full weeks","Agency reports, last 3 weeks (after the cuts)") -> Agency reports, last 3 weeks (after the cuts) | L7: =IF(Calc!C42>Calc!C27,"▲ "&IF(Settings!$C$6="USD","$","€")&TEXT(Calc!C42-Calc!C27,"#,##0")&" over budget","▼ "&IF(Settings!$C$6="USD","$","€")&TEXT(Calc!C27-Calc!C42,"#,##0")&" under budget")&" · "&IF(Calc!C42>Calc!C28,"over","within")&" the maximum" -> ▲ $3,058 over budget · within the maximum
B9: BUDGET CHECK
B10: Measure | D10: Amount | E10: Spent so far | F10: Left | G10: % used | H10: ="Progress (year gone: "&TEXT(Calc!C9,"0%")&")" -> Progress (year gone: 75%) | K10: Status at the current pace
B11: Budget | D11: =Calc!C27 -> 300000 | E11: =Calc!C30 -> 278601.38 | F11: =Calc!C31 -> 21398.616 | G11: =Calc!C33 -> 0.92867128 | H11: =REPT("█",ROUND(MIN(G11,1)*26,0))&REPT("░",26-ROUND(MIN(G11,1)*26,0)) -> ████████████████████████░░ | K11: =IF(Calc!C30>=Calc!C27,"▲ Budget used up",IF(Calc!C42>Calc!C27,"▲ Ends ≈ "&IF(Settings!$C$6="USD","$","€")&TEXT(Calc!C42-Calc!C27,"#,##0")&" over budget","● Ends within budget")) -> ▲ Ends ≈ $3,058 over budget
B12: Maximum (ideally not more) | D12: =Calc!C28 -> 320000 | E12: =Calc!C30 -> 278601.38 | F12: =Calc!C32 -> 41398.616 | G12: =Calc!C34 -> 0.87062933 | H12: =REPT("█",ROUND(MIN(G12,1)*26,0))&REPT("░",26-ROUND(MIN(G12,1)*26,0)) -> ███████████████████████░░░ | K12: =IF(Calc!C30>=Calc!C28,"▲ Maximum passed",IF(Calc!C42>Calc!C28,"▲ Ends ≈ "&IF(Settings!$C$6="USD","$","€")&TEXT(Calc!C42-Calc!C28,"#,##0")&" over the maximum","● Ends ≈ "&IF(Settings!$C$6="USD","$","€")&TEXT(Calc!C28-Calc!C42,"#,##0")&" under the maximum")) -> ● Ends ≈ $16,942 under the maximum
B13: ="By "&TEXT(Calc!C3,"d mmm")&", "&IF(Settings!$C$6="USD","$","€")&TEXT(Calc!C30,"#,##0")&" was spent: "&IF(Settings!$C$6="USD","$","€")&TEXT(ABS(Calc!C36),"#,##0")&IF(Calc!C36>=0," more"," less")&" than an even pace through the year ("&IF(Settings!$C$6="USD","$","€")&TEXT(Calc!C35,"#,##0")&"). Current pace from "&Calc!C40&"." -> By 30 Sep, $278,601 was spent: $54,218 more than an even pace through the year ($224,384). Current pace from the agency reports for W/C 21 Sep – 5 Oct (after the September cuts).
B15: SPEND BY CHANNEL
B16: Channel | D16: ="Spent ("&Settings!$C$6&")" -> Spent (USD) | E16: Share | F16: Last full month | G16: Last 3 full months | H16: Last full week | I16: Counts toward budget? | J16: Billing currency | K16: Note
B17: Meta | D17: =Calc!D20 -> 178067.03 | E17: =Calc!I20 -> 0.63914625 | F17: =Calc!E20 -> 11062.98 | G17: =Calc!F20 -> 40663.58 | H17: =IF(Calc!G20=0,"–",Calc!G20) -> – | I17: =Settings!C22 -> Yes | J17: =Settings!B22 -> USD | K17: =IF(Settings!E22="","",Settings!E22) -> Includes FR_Alibaba (run by PnP's internal team) – confirm it belongs in this budget.
B18: Google Ads | D18: =Calc!D21 -> 100277.78 | E18: =Calc!I21 -> 0.3599328 | F18: =Calc!E21 -> 6854.2282 | G18: =Calc!F21 -> 32249.009 | H18: =IF(Calc!G21=0,"–",Calc!G21) -> – | I18: =Settings!C23 -> Yes | J18: =Settings!B23 -> EUR | K18: =IF(Settings!E23="","",Settings!E23)
B19: ChatGPT Ads | D19: =Calc!D22 -> 256.57921 | E19: =Calc!I22 -> 0.00092095455 | F19: =Calc!E22 -> 256.57921 | G19: =Calc!F22 -> 256.57921 | H19: =IF(Calc!G22=0,"–",Calc!G22) -> – | I19: =Settings!C24 -> Yes | J19: =Settings!B24 -> EUR | K19: =IF(Settings!E24="","",Settings!E24) -> To confirm with Tereza.
B20: LinkedIn Ads | D20: =Calc!D23 -> 0 | E20: =Calc!I23 -> 0 | F20: =Calc!E23 -> 0 | G20: =Calc!F23 -> 0 | H20: =IF(Calc!G23=0,"–",Calc!G23) -> – | I20: =Settings!C25 -> Yes | J20: =Settings!B25 -> USD | K20: =IF(Settings!E25="","",Settings!E25) -> No spend in 2026. Billing currency to check.
B21: Total – all channels | D21: =Calc!D25 -> 278601.38 | E21: =IF(Calc!D25=0,"",1) -> 1 | F21: =Calc!E25 -> 18173.787 | G21: =Calc!F25 -> 73169.168 | H21: =IF(Calc!G25=0,"–",Calc!G25) -> –
B22: 'Last full week' needs daily platform rows: it shows – until the daily exports are pasted.
B24: SPEND BY MONTH AND CHANNEL vs. PLAN | H24: SPEND SO FAR vs. PLAN AND MAXIMUM (CUMULATIVE)
B42: QUARTER BY QUARTER
B43: Quarter | D43: Meta | E43: Google Ads | F43: ChatGPT Ads | G43: LinkedIn Ads | H43: Total – all channels | I43: Counts toward budget | J43: Plan | K43: Status
B44: ="Q1 ("&TEXT(Monthly!A5,"mmm")&"–"&TEXT(Monthly!A7,"mmm")&")" -> Q1 (Jan–Mar) | D44: =SUM(Monthly!C5:C7) -> 75432.1 | E44: =SUM(Monthly!D5:D7) -> 32036.49 | F44: =SUM(Monthly!E5:E7) -> 0 | G44: =SUM(Monthly!F5:F7) -> 0 | H44: =SUM(D44:G44) -> 107468.59 | I44: =SUM(Monthly!H5:H7) -> 107468.59 | J44: =SUM(Monthly!I5:I7) -> 73972.603 | K44: =IF(Settings!$C$5>=EOMONTH(Monthly!A7,0),IF(Settings!$C$5<EOMONTH(Monthly!A10,0),"Complete · last quarter","Complete"),IF(Settings!$C$5>=Monthly!A5,"In progress","Not started")) -> Complete
B45: ="Q2 ("&TEXT(Monthly!A8,"mmm")&"–"&TEXT(Monthly!A10,"mmm")&")" -> Q2 (Apr–Jun) | D45: =SUM(Monthly!C8:C10) -> 61971.35 | E45: =SUM(Monthly!D8:D10) -> 35992.276 | F45: =SUM(Monthly!E8:E10) -> 0 | G45: =SUM(Monthly!F8:F10) -> 0 | H45: =SUM(D45:G45) -> 97963.626 | I45: =SUM(Monthly!H8:H10) -> 97963.626 | J45: =SUM(Monthly!I8:I10) -> 74794.521 | K45: =IF(Settings!$C$5>=EOMONTH(Monthly!A10,0),IF(Settings!$C$5<EOMONTH(Monthly!A13,0),"Complete · last quarter","Complete"),IF(Settings!$C$5>=Monthly!A8,"In progress","Not started")) -> Complete
B46: ="Q3 ("&TEXT(Monthly!A11,"mmm")&"–"&TEXT(Monthly!A13,"mmm")&")" -> Q3 (Jul–Sep) | D46: =SUM(Monthly!C11:C13) -> 40663.58 | E46: =SUM(Monthly!D11:D13) -> 32249.009 | F46: =SUM(Monthly!E11:E13) -> 256.57921 | G46: =SUM(Monthly!F11:F13) -> 0 | H46: =SUM(D46:G46) -> 73169.168 | I46: =SUM(Monthly!H11:H13) -> 73169.168 | J46: =SUM(Monthly!I11:I13) -> 75616.438 | K46: =IF(Settings!$C$5>=EOMONTH(Monthly!A13,0),IF(Settings!$C$5<EOMONTH(Monthly!A16,0),"Complete · last quarter","Complete"),IF(Settings!$C$5>=Monthly!A11,"In progress","Not started")) -> Complete · last quarter
B47: ="Q4 ("&TEXT(Monthly!A14,"mmm")&"–"&TEXT(Monthly!A16,"mmm")&")" -> Q4 (Oct–Dec) | D47: =SUM(Monthly!C14:C16) -> 0 | E47: =SUM(Monthly!D14:D16) -> 0 | F47: =SUM(Monthly!E14:E16) -> 0 | G47: =SUM(Monthly!F14:F16) -> 0 | H47: =SUM(D47:G47) -> 0 | I47: =SUM(Monthly!H14:H16) -> 0 | J47: =SUM(Monthly!I14:I16) -> 75616.438 | K47: =IF(Settings!$C$5>=EOMONTH(Monthly!A16,0),"Complete",IF(Settings!$C$5>=Monthly!A14,"In progress","Not started")) -> Not started
B48: Total | D48: =SUM(D44:D47) -> 178067.03 | E48: =SUM(E44:E47) -> 100277.78 | F48: =SUM(F44:F47) -> 256.57921 | G48: =SUM(G44:G47) -> 0 | H48: =SUM(H44:H47) -> 278601.38 | I48: =SUM(I44:I47) -> 278601.38 | J48: =SUM(J44:J47) -> 300000
B50: YEAR-END OUTLOOK (budget channels)
B51: If we spend from now on at… | F51: ="Per week ("&Settings!$C$6&")" -> Per week (USD) | G51: Year-end total | H51: vs. budget | I51: vs. maximum | J51: What it means
B52: ="…the current pace" -> …the current pace | F52: =Calc!C39 -> 1860.8593 | G52: =Calc!C42 -> 303058.39 | H52: =G52-Calc!$C$27 -> 3058.3922 | I52: =G52-Calc!$C$28 -> -16941.608 | J52: ="Source: "&Calc!C40 -> Source: the agency reports for W/C 21 Sep – 5 Oct (after the September cuts)
B53: ="…a pace that lands exactly on the budget" -> …a pace that lands exactly on the budget | F53: =MAX(0,Calc!C43) -> 1628.1555 | G53: =Calc!C27 -> 300000 | H53: =G53-Calc!$C$27 -> 0 | I53: =G53-Calc!$C$28 -> -20000 | J53: =IF(Calc!C31<=0,"The budget is already used up",IF(Calc!C39=0,"",IF(Calc!C43<Calc!C39,TEXT(1-Calc!C43/Calc!C39,"0%")&" less per week than the current pace",TEXT(Calc!C43/Calc!C39-1,"0%")&" more per week than the current pace"))) -> 13% less per week than the current pace
B54: ="…a pace that uses the maximum" -> …a pace that uses the maximum | F54: =MAX(0,Calc!C44) -> 3149.8947 | G54: =Calc!C28 -> 320000 | H54: =G54-Calc!$C$27 -> 20000 | I54: =G54-Calc!$C$28 -> 0 | J54: =IF(Calc!C32<=0,"The maximum is already passed",IF(Calc!C39=0,"",IF(Calc!C44<Calc!C39,TEXT(1-Calc!C44/Calc!C39,"0%")&" less per week than the current pace",TEXT(Calc!C44/Calc!C39-1,"0%")&" more per week than the current pace"))) -> 69% more per week than the current pace
B55: ="…last month's pace ("&TEXT(Calc!C11,"mmmm")&", before the cuts)" -> …last month's pace (September, before the cuts) | F55: =Calc!C45/Calc!C17*7 -> 4240.5504 | G55: =Calc!C47 -> 334334.33 | H55: =G55-Calc!$C$27 -> 34334.332 | I55: =G55-Calc!$C$28 -> 14334.332 | J55: ="For reference" -> For reference
B57: WHERE THE MONEY WENT – BY REGION | H57: TOP MARKETS (year to date)
B73: Region and market come from the location code in each campaign name – see the 'By location & type' and 'Campaigns' tabs. Sources, exchange rate and how to update: 'How to update' tab.

Sheet Weekly
A1: Weekly spend
A2: ="Weeks run Monday to Sunday · amounts in "&Settings!$C$6&" · from the daily platform exports. Yellow columns are typed by you." -> Weeks run Monday to Sunday · amounts in USD · from the daily platform exports. Yellow columns are typed by you.
A3: Data up to: | C3: =Settings!$C$5 -> 46295 | D3: Last full week ends: | F3: =Calc!C13 -> 46292 | H3: Spend before October fills in once the daily platform exports are pasted. Until then, the agency's weekly figures are on the 'Agency reports' tab and their notes are in column R.
A4: Week | B4: Starts (Mon) | C4: Ends (Sun) | D4: Meta | E4: Google Ads | F4: ChatGPT Ads | G4: LinkedIn Ads | H4: Total – all channels | I4: Counts toward budget | J4: Plan (budget spread evenly by day) | K4: Over (+) / under (−) plan | L4: Meta conversions | M4: Meta cost per conversion | N4: Google conversions | O4: Google cost per conversion | P4: MQLs – paid social (HubSpot, optional) | Q4: MQLs – paid search (HubSpot, optional) | R4: Notes – what happened this week | S4: Chart label
A5: 1 | B5: =Settings!$C$13+7*(A5-1) -> 46020 | C5: =B5+6 -> 46026 | D5: =SUMIFS('Meta data'!$I$3:$I$20000,'Meta data'!$A$3:$A$20000,">="&$B5,'Meta data'!$A$3:$A$20000,"<="&$C5,'Meta data'!$G$3:$G$20000,"<>Month total") -> 0 | E5: =SUMIFS('Google data'!$I$3:$I$20000,'Google data'!$A$3:$A$20000,">="&$B5,'Google data'!$A$3:$A$20000,"<="&$C5,'Google data'!$G$3:$G$20000,"<>Month total") -> 0 | F5: =SUMIFS('ChatGPT data'!$I$3:$I$20000,'ChatGPT data'!$A$3:$A$20000,">="&$B5,'ChatGPT data'!$A$3:$A$20000,"<="&$C5,'ChatGPT data'!$G$3:$G$20000,"<>Month total") -> 0 | G5: =SUMIFS('LinkedIn data'!$I$3:$I$20000,'LinkedIn data'!$A$3:$A$20000,">="&$B5,'LinkedIn data'!$A$3:$A$20000,"<="&$C5,'LinkedIn data'!$G$3:$G$20000,"<>Month total") -> 0 | H5: =SUM(D5:G5) -> 0 | I5: =D5*(Settings!$C$22="Yes")+E5*(Settings!$C$23="Yes")+F5*(Settings!$C$24="Yes")+G5*(Settings!$C$25="Yes") -> 0 | J5: =Settings!$D$16*MAX(0,MIN(C5,Settings!$C$11)-MAX(B5,Settings!$C$10)+1)/(Settings!$C$11-Settings!$C$10+1) -> 3287.6712 | K5: =IF(OR(C5>$C$3,I5=0),"",I5-J5) | L5: =SUMIFS('Meta data'!$F$3:$F$20000,'Meta data'!$A$3:$A$20000,">="&$B5,'Meta data'!$A$3:$A$20000,"<="&$C5,'Meta data'!$G$3:$G$20000,"<>Month total") -> 0 | M5: =IF(L5=0,"",D5/L5) | N5: =SUMIFS('Google data'!$F$3:$F$20000,'Google data'!$A$3:$A$20000,">="&$B5,'Google data'!$A$3:$A$20000,"<="&$C5,'Google data'!$G$3:$G$20000,"<>Month total") -> 0 | O5: =IF(N5=0,"",E5/N5) | R5: Agency: Paused the Health ad set on Meta EMEA. Next: prepare the location strategy, launch a Meta retargeting campaign for job-application (JTP) conversions, build a PMax asset group from the Quantum ad. | S5: =TEXT(B5,"d mmm") -> 29 Dec
A6: 2 | B6: =Settings!$C$13+7*(A6-1) -> 46027 | C6: =B6+6 -> 46033 | D6: =SUMIFS('Meta data'!$I$3:$I$20000,'Meta data'!$A$3:$A$20000,">="&$B6,'Meta data'!$A$3:$A$20000,"<="&$C6,'Meta data'!$G$3:$G$20000,"<>Month total") -> 0 | E6: =SUMIFS('Google data'!$I$3:$I$20000,'Google data'!$A$3:$A$20000,">="&$B6,'Google data'!$A$3:$A$20000,"<="&$C6,'Google data'!$G$3:$G$20000,"<>Month total") -> 0 | F6: =SUMIFS('ChatGPT data'!$I$3:$I$20000,'ChatGPT data'!$A$3:$A$20000,">="&$B6,'ChatGPT data'!$A$3:$A$20000,"<="&$C6,'ChatGPT data'!$G$3:$G$20000,"<>Month total") -> 0 | G6: =SUMIFS('LinkedIn data'!$I$3:$I$20000,'LinkedIn data'!$A$3:$A$20000,">="&$B6,'LinkedIn data'!$A$3:$A$20000,"<="&$C6,'LinkedIn data'!$G$3:$G$20000,"<>Month total") -> 0 | H6: =SUM(D6:G6) -> 0 | I6: =D6*(Settings!$C$22="Yes")+E6*(Settings!$C$23="Yes")+F6*(Settings!$C$24="Yes")+G6*(Settings!$C$25="Yes") -> 0 | J6: =Settings!$D$16*MAX(0,MIN(C6,Settings!$C$11)-MAX(B6,Settings!$C$10)+1)/(Settings!$C$11-Settings!$C$10+1) -> 5753.4247 | K6: =IF(OR(C6>$C$3,I6=0),"",I6-J6) | L6: =SUMIFS('Meta data'!$F$3:$F$20000,'Meta data'!$A$3:$A$20000,">="&$B6,'Meta data'!$A$3:$A$20000,"<="&$C6,'Meta data'!$G$3:$G$20000,"<>Month total") -> 0 | M6: =IF(L6=0,"",D6/L6) | N6: =SUMIFS('Google data'!$F$3:$F$20000,'Google data'!$A$3:$A$20000,">="&$B6,'Google data'!$A$3:$A$20000,"<="&$C6,'Google data'!$G$3:$G$20000,"<>Month total") -> 0 | O6: =IF(N6=0,"",E6/N6) | R6: Agency: Added Meta JTP retargeting campaigns, which pushed CPL up. Google EMEA non-brand dropped while PMax and Brand rose. Plan: agree and start the new geo structure. | S6: =TEXT(B6,"d mmm") -> 5 Jan
A7: 3 | B7: =Settings!$C$13+7*(A7-1) -> 46034 | C7: =B7+6 -> 46040 | D7: =SUMIFS('Meta data'!$I$3:$I$20000,'Meta data'!$A$3:$A$20000,">="&$B7,'Meta data'!$A$3:$A$20000,"<="&$C7,'Meta data'!$G$3:$G$20000,"<>Month total") -> 0 | E7: =SUMIFS('Google data'!$I$3:$I$20000,'Google data'!$A$3:$A$20000,">="&$B7,'Google data'!$A$3:$A$20000,"<="&$C7,'Google data'!$G$3:$G$20000,"<>Month total") -> 0 | F7: =SUMIFS('ChatGPT data'!$I$3:$I$20000,'ChatGPT data'!$A$3:$A$20000,">="&$B7,'ChatGPT data'!$A$3:$A$20000,"<="&$C7,'ChatGPT data'!$G$3:$G$20000,"<>Month total") -> 0 | G7: =SUMIFS('LinkedIn data'!$I$3:$I$20000,'LinkedIn data'!$A$3:$A$20000,">="&$B7,'LinkedIn data'!$A$3:$A$20000,"<="&$C7,'LinkedIn data'!$G$3:$G$20000,"<>Month total") -> 0 | H7: =SUM(D7:G7) -> 0 | I7: =D7*(Settings!$C$22="Yes")+E7*(Settings!$C$23="Yes")+F7*(Settings!$C$24="Yes")+G7*(Settings!$C$25="Yes") -> 0 | J7: =Settings!$D$16*MAX(0,MIN(C7,Settings!$C$11)-MAX(B7,Settings!$C$10)+1)/(Settings!$C$11-Settings!$C$10+1) -> 5753.4247 | K7: =IF(OR(C7>$C$3,I7=0),"",I7-J7) | L7: =SUMIFS('Meta data'!$F$3:$F$20000,'Meta data'!$A$3:$A$20000,">="&$B7,'Meta data'!$A$3:$A$20000,"<="&$C7,'Meta data'!$G$3:$G$20000,"<>Month total") -> 0 | M7: =IF(L7=0,"",D7/L7) | N7: =SUMIFS('Google data'!$F$3:$F$20000,'Google data'!$A$3:$A$20000,">="&$B7,'Google data'!$A$3:$A$20000,"<="&$C7,'Google data'!$G$3:$G$20000,"<>Month total") -> 0 | O7: =IF(N7=0,"",E7/N7) | R7: Agency: New Google structure live; EMEA location campaigns had no leads yet. Meta being restructured for the geo strategy. Paused the Health push in USCA. | S7: =TEXT(B7,"d mmm") -> 12 Jan
A8: 4 | B8: =Settings!$C$13+7*(A8-1) -> 46041 | C8: =B8+6 -> 46047 | D8: =SUMIFS('Meta data'!$I$3:$I$20000,'Meta data'!$A$3:$A$20000,">="&$B8,'Meta data'!$A$3:$A$20000,"<="&$C8,'Meta data'!$G$3:$G$20000,"<>Month total") -> 0 | E8: =SUMIFS('Google data'!$I$3:$I$20000,'Google data'!$A$3:$A$20000,">="&$B8,'Google data'!$A$3:$A$20000,"<="&$C8,'Google data'!$G$3:$G$20000,"<>Month total") -> 0 | F8: =SUMIFS('ChatGPT data'!$I$3:$I$20000,'ChatGPT data'!$A$3:$A$20000,">="&$B8,'ChatGPT data'!$A$3:$A$20000,"<="&$C8,'ChatGPT data'!$G$3:$G$20000,"<>Month total") -> 0 | G8: =SUMIFS('LinkedIn data'!$I$3:$I$20000,'LinkedIn data'!$A$3:$A$20000,">="&$B8,'LinkedIn data'!$A$3:$A$20000,"<="&$C8,'LinkedIn data'!$G$3:$G$20000,"<>Month total") -> 0 | H8: =SUM(D8:G8) -> 0 | I8: =D8*(Settings!$C$22="Yes")+E8*(Settings!$C$23="Yes")+F8*(Settings!$C$24="Yes")+G8*(Settings!$C$25="Yes") -> 0 | J8: =Settings!$D$16*MAX(0,MIN(C8,Settings!$C$11)-MAX(B8,Settings!$C$10)+1)/(Settings!$C$11-Settings!$C$10+1) -> 5753.4247 | K8: =IF(OR(C8>$C$3,I8=0),"",I8-J8) | L8: =SUMIFS('Meta data'!$F$3:$F$20000,'Meta data'!$A$3:$A$20000,">="&$B8,'Meta data'!$A$3:$A$20000,"<="&$C8,'Meta data'!$G$3:$G$20000,"<>Month total") -> 0 | M8: =IF(L8=0,"",D8/L8) | N8: =SUMIFS('Google data'!$F$3:$F$20000,'Google data'!$A$3:$A$20000,">="&$B8,'Google data'!$A$3:$A$20000,"<="&$C8,'Google data'!$G$3:$G$20000,"<>Month total") -> 0 | O8: =IF(N8=0,"",E8/N8) | R8: Agency: Spend down 15% WoW due to the new structure. Splitting California out of USCA hurt Meta. Google pushed new locations: more spend, no extra leads. | S8: =TEXT(B8,"d mmm") -> 19 Jan
A9: 5 | B9: =Settings!$C$13+7*(A9-1) -> 46048 | C9: =B9+6 -> 46054 | D9: =SUMIFS('Meta data'!$I$3:$I$20000,'Meta data'!$A$3:$A$20000,">="&$B9,'Meta data'!$A$3:$A$20000,"<="&$C9,'Meta data'!$G$3:$G$20000,"<>Month total") -> 0 | E9: =SUMIFS('Google data'!$I$3:$I$20000,'Google data'!$A$3:$A$20000,">="&$B9,'Google data'!$A$3:$A$20000,"<="&$C9,'Google data'!$G$3:$G$20000,"<>Month total") -> 0 | F9: =SUMIFS('ChatGPT data'!$I$3:$I$20000,'ChatGPT data'!$A$3:$A$20000,">="&$B9,'ChatGPT data'!$A$3:$A$20000,"<="&$C9,'ChatGPT data'!$G$3:$G$20000,"<>Month total") -> 0 | G9: =SUMIFS('LinkedIn data'!$I$3:$I$20000,'LinkedIn data'!$A$3:$A$20000,">="&$B9,'LinkedIn data'!$A$3:$A$20000,"<="&$C9,'LinkedIn data'!$G$3:$G$20000,"<>Month total") -> 0 | H9: =SUM(D9:G9) -> 0 | I9: =D9*(Settings!$C$22="Yes")+E9*(Settings!$C$23="Yes")+F9*(Settings!$C$24="Yes")+G9*(Settings!$C$25="Yes") -> 0 | J9: =Settings!$D$16*MAX(0,MIN(C9,Settings!$C$11)-MAX(B9,Settings!$C$10)+1)/(Settings!$C$11-Settings!$C$10+1) -> 5753.4247 | K9: =IF(OR(C9>$C$3,I9=0),"",I9-J9) | L9: =SUMIFS('Meta data'!$F$3:$F$20000,'Meta data'!$A$3:$A$20000,">="&$B9,'Meta data'!$A$3:$A$20000,"<="&$C9,'Meta data'!$G$3:$G$20000,"<>Month total") -> 0 | M9: =IF(L9=0,"",D9/L9) | N9: =SUMIFS('Google data'!$F$3:$F$20000,'Google data'!$A$3:$A$20000,">="&$B9,'Google data'!$A$3:$A$20000,"<="&$C9,'Google data'!$G$3:$G$20000,"<>Month total") -> 0 | O9: =IF(N9=0,"",E9/N9) | R9: Agency: Google CPL rose as spend moved from PMax to Search. NY, NJ, AZ, IN and Washington had no leads. Quantum was the top Meta ad. | S9: =TEXT(B9,"d mmm") -> 26 Jan
A10: 6 | B10: =Settings!$C$13+7*(A10-1) -> 46055 | C10: =B10+6 -> 46061 | D10: =SUMIFS('Meta data'!$I$3:$I$20000,'Meta data'!$A$3:$A$20000,">="&$B10,'Meta data'!$A$3:$A$20000,"<="&$C10,'Meta data'!$G$3:$G$20000,"<>Month total") -> 0 | E10: =SUMIFS('Google data'!$I$3:$I$20000,'Google data'!$A$3:$A$20000,">="&$B10,'Google data'!$A$3:$A$20000,"<="&$C10,'Google data'!$G$3:$G$20000,"<>Month total") -> 0 | F10: =SUMIFS('ChatGPT data'!$I$3:$I$20000,'ChatGPT data'!$A$3:$A$20000,">="&$B10,'ChatGPT data'!$A$3:$A$20000,"<="&$C10,'ChatGPT data'!$G$3:$G$20000,"<>Month total") -> 0 | G10: =SUMIFS('LinkedIn data'!$I$3:$I$20000,'LinkedIn data'!$A$3:$A$20000,">="&$B10,'LinkedIn data'!$A$3:$A$20000,"<="&$C10,'LinkedIn data'!$G$3:$G$20000,"<>Month total") -> 0 | H10: =SUM(D10:G10) -> 0 | I10: =D10*(Settings!$C$22="Yes")+E10*(Settings!$C$23="Yes")+F10*(Settings!$C$24="Yes")+G10*(Settings!$C$25="Yes") -> 0 | J10: =Settings!$D$16*MAX(0,MIN(C10,Settings!$C$11)-MAX(B10,Settings!$C$10)+1)/(Settings!$C$11-Settings!$C$10+1) -> 5753.4247 | K10: =IF(OR(C10>$C$3,I10=0),"",I10-J10) | L10: =SUMIFS('Meta data'!$F$3:$F$20000,'Meta data'!$A$3:$A$20000,">="&$B10,'Meta data'!$A$3:$A$20000,"<="&$C10,'Meta data'!$G$3:$G$20000,"<>Month total") -> 0 | M10: =IF(L10=0,"",D10/L10) | N10: =SUMIFS('Google data'!$F$3:$F$20000,'Google data'!$A$3:$A$20000,">="&$B10,'Google data'!$A$3:$A$20000,"<="&$C10,'Google data'!$G$3:$G$20000,"<>Month total") -> 0 | O10: =IF(N10=0,"",E10/N10) | R10: Agency: Google clicks up 188% but CR fell; US campaigns underperformed. Meta Spanish Grid ads lowered CPL. Plan: increase spend in all regions. | S10: =TEXT(B10,"d mmm") -> 2 Feb
A11: 7 | B11: =Settings!$C$13+7*(A11-1) -> 46062 | C11: =B11+6 -> 46068 | D11: =SUMIFS('Meta data'!$I$3:$I$20000,'Meta data'!$A$3:$A$20000,">="&$B11,'Meta data'!$A$3:$A$20000,"<="&$C11,'Meta data'!$G$3:$G$20000,"<>Month total") -> 0 | E11: =SUMIFS('Google data'!$I$3:$I$20000,'Google data'!$A$3:$A$20000,">="&$B11,'Google data'!$A$3:$A$20000,"<="&$C11,'Google data'!$G$3:$G$20000,"<>Month total") -> 0 | F11: =SUMIFS('ChatGPT data'!$I$3:$I$20000,'ChatGPT data'!$A$3:$A$20000,">="&$B11,'ChatGPT data'!$A$3:$A$20000,"<="&$C11,'ChatGPT data'!$G$3:$G$20000,"<>Month total") -> 0 | G11: =SUMIFS('LinkedIn data'!$I$3:$I$20000,'LinkedIn data'!$A$3:$A$20000,">="&$B11,'LinkedIn data'!$A$3:$A$20000,"<="&$C11,'LinkedIn data'!$G$3:$G$20000,"<>Month total") -> 0 | H11: =SUM(D11:G11) -> 0 | I11: =D11*(Settings!$C$22="Yes")+E11*(Settings!$C$23="Yes")+F11*(Settings!$C$24="Yes")+G11*(Settings!$C$25="Yes") -> 0 | J11: =Settings!$D$16*MAX(0,MIN(C11,Settings!$C$11)-MAX(B11,Settings!$C$10)+1)/(Settings!$C$11-Settings!$C$10+1) -> 5753.4247 | K11: =IF(OR(C11>$C$3,I11=0),"",I11-J11) | L11: =SUMIFS('Meta data'!$F$3:$F$20000,'Meta data'!$A$3:$A$20000,">="&$B11,'Meta data'!$A$3:$A$20000,"<="&$C11,'Meta data'!$G$3:$G$20000,"<>Month total") -> 0 | M11: =IF(L11=0,"",D11/L11) | N11: =SUMIFS('Google data'!$F$3:$F$20000,'Google data'!$A$3:$A$20000,">="&$B11,'Google data'!$A$3:$A$20000,"<="&$C11,'Google data'!$G$3:$G$20000,"<>Month total") -> 0 | O11: =IF(N11=0,"",E11/N11) | R11: Agency: Meta location campaigns launched Thursday; spend jumped. Broader Google keywords added; some locations underspending (may move to Max Clicks). | S11: =TEXT(B11,"d mmm") -> 9 Feb
A12: 8 | B12: =Settings!$C$13+7*(A12-1) -> 46069 | C12: =B12+6 -> 46075 | D12: =SUMIFS('Meta data'!$I$3:$I$20000,'Meta data'!$A$3:$A$20000,">="&$B12,'Meta data'!$A$3:$A$20000,"<="&$C12,'Meta data'!$G$3:$G$20000,"<>Month total") -> 0 | E12: =SUMIFS('Google data'!$I$3:$I$20000,'Google data'!$A$3:$A$20000,">="&$B12,'Google data'!$A$3:$A$20000,"<="&$C12,'Google data'!$G$3:$G$20000,"<>Month total") -> 0 | F12: =SUMIFS('ChatGPT data'!$I$3:$I$20000,'ChatGPT data'!$A$3:$A$20000,">="&$B12,'ChatGPT data'!$A$3:$A$20000,"<="&$C12,'ChatGPT data'!$G$3:$G$20000,"<>Month total") -> 0 | G12: =SUMIFS('LinkedIn data'!$I$3:$I$20000,'LinkedIn data'!$A$3:$A$20000,">="&$B12,'LinkedIn data'!$A$3:$A$20000,"<="&$C12,'LinkedIn data'!$G$3:$G$20000,"<>Month total") -> 0 | H12: =SUM(D12:G12) -> 0 | I12: =D12*(Settings!$C$22="Yes")+E12*(Settings!$C$23="Yes")+F12*(Settings!$C$24="Yes")+G12*(Settings!$C$25="Yes") -> 0 | J12: =Settings!$D$16*MAX(0,MIN(C12,Settings!$C$11)-MAX(B12,Settings!$C$10)+1)/(Settings!$C$11-Settings!$C$10+1) -> 5753.4247 | K12: =IF(OR(C12>$C$3,I12=0),"",I12-J12) | L12: =SUMIFS('Meta data'!$F$3:$F$20000,'Meta data'!$A$3:$A$20000,">="&$B12,'Meta data'!$A$3:$A$20000,"<="&$C12,'Meta data'!$G$3:$G$20000,"<>Month total") -> 0 | M12: =IF(L12=0,"",D12/L12) | N12: =SUMIFS('Google data'!$F$3:$F$20000,'Google data'!$A$3:$A$20000,">="&$B12,'Google data'!$A$3:$A$20000,"<="&$C12,'Google data'!$G$3:$G$20000,"<>Month total") -> 0 | O12: =IF(N12=0,"",E12/N12) | R12: Agency: Both Google Global search campaigns budget-limited; agency asks to move budget "even if out of plan". Indiana the worst Meta location. | S12: =TEXT(B12,"d mmm") -> 16 Feb
A13: 9 | B13: =Settings!$C$13+7*(A13-1) -> 46076 | C13: =B13+6 -> 46082 | D13: =SUMIFS('Meta data'!$I$3:$I$20000,'Meta data'!$A$3:$A$20000,">="&$B13,'Meta data'!$A$3:$A$20000,"<="&$C13,'Meta data'!$G$3:$G$20000,"<>Month total") -> 0 | E13: =SUMIFS('Google data'!$I$3:$I$20000,'Google data'!$A$3:$A$20000,">="&$B13,'Google data'!$A$3:$A$20000,"<="&$C13,'Google data'!$G$3:$G$20000,"<>Month total") -> 0 | F13: =SUMIFS('ChatGPT data'!$I$3:$I$20000,'ChatGPT data'!$A$3:$A$20000,">="&$B13,'ChatGPT data'!$A$3:$A$20000,"<="&$C13,'ChatGPT data'!$G$3:$G$20000,"<>Month total") -> 0 | G13: =SUMIFS('LinkedIn data'!$I$3:$I$20000,'LinkedIn data'!$A$3:$A$20000,">="&$B13,'LinkedIn data'!$A$3:$A$20000,"<="&$C13,'LinkedIn data'!$G$3:$G$20000,"<>Month total") -> 0 | H13: =SUM(D13:G13) -> 0 | I13: =D13*(Settings!$C$22="Yes")+E13*(Settings!$C$23="Yes")+F13*(Settings!$C$24="Yes")+G13*(Settings!$C$25="Yes") -> 0 | J13: =Settings!$D$16*MAX(0,MIN(C13,Settings!$C$11)-MAX(B13,Settings!$C$10)+1)/(Settings!$C$11-Settings!$C$10+1) -> 5753.4247 | K13: =IF(OR(C13>$C$3,I13=0),"",I13-J13) | L13: =SUMIFS('Meta data'!$F$3:$F$20000,'Meta data'!$A$3:$A$20000,">="&$B13,'Meta data'!$A$3:$A$20000,"<="&$C13,'Meta data'!$G$3:$G$20000,"<>Month total") -> 0 | M13: =IF(L13=0,"",D13/L13) | N13: =SUMIFS('Google data'!$F$3:$F$20000,'Google data'!$A$3:$A$20000,">="&$B13,'Google data'!$A$3:$A$20000,"<="&$C13,'Google data'!$G$3:$G$20000,"<>Month total") -> 0 | O13: =IF(N13=0,"",E13/N13) | R13: Agency: Google YouTube campaigns ended. Search improved but Global still budget-limited. Meta CPM rose across campaigns. | S13: =TEXT(B13,"d mmm") -> 23 Feb
A14: 10 | B14: =Settings!$C$13+7*(A14-1) -> 46083 | C14: =B14+6 -> 46089 | D14: =SUMIFS('Meta data'!$I$3:$I$20000,'Meta data'!$A$3:$A$20000,">="&$B14,'Meta data'!$A$3:$A$20000,"<="&$C14,'Meta data'!$G$3:$G$20000,"<>Month total") -> 0 | E14: =SUMIFS('Google data'!$I$3:$I$20000,'Google data'!$A$3:$A$20000,">="&$B14,'Google data'!$A$3:$A$20000,"<="&$C14,'Google data'!$G$3:$G$20000,"<>Month total") -> 0 | F14: =SUMIFS('ChatGPT data'!$I$3:$I$20000,'ChatGPT data'!$A$3:$A$20000,">="&$B14,'ChatGPT data'!$A$3:$A$20000,"<="&$C14,'ChatGPT data'!$G$3:$G$20000,"<>Month total") -> 0 | G14: =SUMIFS('LinkedIn data'!$I$3:$I$20000,'LinkedIn data'!$A$3:$A$20000,">="&$B14,'LinkedIn data'!$A$3:$A$20000,"<="&$C14,'LinkedIn data'!$G$3:$G$20000,"<>Month total") -> 0 | H14: =SUM(D14:G14) -> 0 | I14: =D14*(Settings!$C$22="Yes")+E14*(Settings!$C$23="Yes")+F14*(Settings!$C$24="Yes")+G14*(Settings!$C$25="Yes") -> 0 | J14: =Settings!$D$16*MAX(0,MIN(C14,Settings!$C$11)-MAX(B14,Settings!$C$10)+1)/(Settings!$C$11-Settings!$C$10+1) -> 5753.4247 | K14: =IF(OR(C14>$C$3,I14=0),"",I14-J14) | L14: =SUMIFS('Meta data'!$F$3:$F$20000,'Meta data'!$A$3:$A$20000,">="&$B14,'Meta data'!$A$3:$A$20000,"<="&$C14,'Meta data'!$G$3:$G$20000,"<>Month total") -> 0 | M14: =IF(L14=0,"",D14/L14) | N14: =SUMIFS('Google data'!$F$3:$F$20000,'Google data'!$A$3:$A$20000,">="&$B14,'Google data'!$A$3:$A$20000,"<="&$C14,'Google data'!$G$3:$G$20000,"<>Month total") -> 0 | O14: =IF(N14=0,"",E14/N14) | R14: Agency: Tightened Google targets in some locations; added broad keywords in UK, France, Texas. Agency asks to use HubSpot as Google's conversion source. | S14: =TEXT(B14,"d mmm") -> 2 Mar
A15: 11 | B15: =Settings!$C$13+7*(A15-1) -> 46090 | C15: =B15+6 -> 46096 | D15: =SUMIFS('Meta data'!$I$3:$I$20000,'Meta data'!$A$3:$A$20000,">="&$B15,'Meta data'!$A$3:$A$20000,"<="&$C15,'Meta data'!$G$3:$G$20000,"<>Month total") -> 0 | E15: =SUMIFS('Google data'!$I$3:$I$20000,'Google data'!$A$3:$A$20000,">="&$B15,'Google data'!$A$3:$A$20000,"<="&$C15,'Google data'!$G$3:$G$20000,"<>Month total") -> 0 | F15: =SUMIFS('ChatGPT data'!$I$3:$I$20000,'ChatGPT data'!$A$3:$A$20000,">="&$B15,'ChatGPT data'!$A$3:$A$20000,"<="&$C15,'ChatGPT data'!$G$3:$G$20000,"<>Month total") -> 0 | G15: =SUMIFS('LinkedIn data'!$I$3:$I$20000,'LinkedIn data'!$A$3:$A$20000,">="&$B15,'LinkedIn data'!$A$3:$A$20000,"<="&$C15,'LinkedIn data'!$G$3:$G$20000,"<>Month total") -> 0 | H15: =SUM(D15:G15) -> 0 | I15: =D15*(Settings!$C$22="Yes")+E15*(Settings!$C$23="Yes")+F15*(Settings!$C$24="Yes")+G15*(Settings!$C$25="Yes") -> 0 | J15: =Settings!$D$16*MAX(0,MIN(C15,Settings!$C$11)-MAX(B15,Settings!$C$10)+1)/(Settings!$C$11-Settings!$C$10+1) -> 5753.4247 | K15: =IF(OR(C15>$C$3,I15=0),"",I15-J15) | L15: =SUMIFS('Meta data'!$F$3:$F$20000,'Meta data'!$A$3:$A$20000,">="&$B15,'Meta data'!$A$3:$A$20000,"<="&$C15,'Meta data'!$G$3:$G$20000,"<>Month total") -> 0 | M15: =IF(L15=0,"",D15/L15) | N15: =SUMIFS('Google data'!$F$3:$F$20000,'Google data'!$A$3:$A$20000,">="&$B15,'Google data'!$A$3:$A$20000,"<="&$C15,'Google data'!$G$3:$G$20000,"<>Month total") -> 0 | O15: =IF(N15=0,"",E15/N15) | R15: Agency: Google spend raised after better in-platform results. Large Google vs HubSpot gap flagged. NY, NJ and AZ Meta campaigns worsening. | S15: =TEXT(B15,"d mmm") -> 9 Mar
A16: 12 | B16: =Settings!$C$13+7*(A16-1) -> 46097 | C16: =B16+6 -> 46103 | D16: =SUMIFS('Meta data'!$I$3:$I$20000,'Meta data'!$A$3:$A$20000,">="&$B16,'Meta data'!$A$3:$A$20000,"<="&$C16,'Meta data'!$G$3:$G$20000,"<>Month total") -> 0 | E16: =SUMIFS('Google data'!$I$3:$I$20000,'Google data'!$A$3:$A$20000,">="&$B16,'Google data'!$A$3:$A$20000,"<="&$C16,'Google data'!$G$3:$G$20000,"<>Month total") -> 0 | F16: =SUMIFS('ChatGPT data'!$I$3:$I$20000,'ChatGPT data'!$A$3:$A$20000,">="&$B16,'ChatGPT data'!$A$3:$A$20000,"<="&$C16,'ChatGPT data'!$G$3:$G$20000,"<>Month total") -> 0 | G16: =SUMIFS('LinkedIn data'!$I$3:$I$20000,'LinkedIn data'!$A$3:$A$20000,">="&$B16,'LinkedIn data'!$A$3:$A$20000,"<="&$C16,'LinkedIn data'!$G$3:$G$20000,"<>Month total") -> 0 | H16: =SUM(D16:G16) -> 0 | I16: =D16*(Settings!$C$22="Yes")+E16*(Settings!$C$23="Yes")+F16*(Settings!$C$24="Yes")+G16*(Settings!$C$25="Yes") -> 0 | J16: =Settings!$D$16*MAX(0,MIN(C16,Settings!$C$11)-MAX(B16,Settings!$C$10)+1)/(Settings!$C$11-Settings!$C$10+1) -> 5753.4247 | K16: =IF(OR(C16>$C$3,I16=0),"",I16-J16) | L16: =SUMIFS('Meta data'!$F$3:$F$20000,'Meta data'!$A$3:$A$20000,">="&$B16,'Meta data'!$A$3:$A$20000,"<="&$C16,'Meta data'!$G$3:$G$20000,"<>Month total") -> 0 | M16: =IF(L16=0,"",D16/L16) | N16: =SUMIFS('Google data'!$F$3:$F$20000,'Google data'!$A$3:$A$20000,">="&$B16,'Google data'!$A$3:$A$20000,"<="&$C16,'Google data'!$G$3:$G$20000,"<>Month total") -> 0 | O16: =IF(N16=0,"",E16/N16) | R16: Agency: Google Global EMEA at 0 leads despite a 60% spend cut; under review. Demand Gen running in Texas and Florida. Meta "All" campaigns refresh planned. | S16: =TEXT(B16,"d mmm") -> 16 Mar
... A45: 41 | B45: =Settings!$C$13+7*(A45-1) -> 46300 | C45: =B45+6 -> 46306 | D45: =SUMIFS('Meta data'!$I$3:$I$20000,'Meta data'!$A$3:$A$20000,">="&$B45,'Meta data'!$A$3:$A$20000,"<="&$C45,'Meta data'!$G$3:$G$20000,"<>Month total") -> 0 | E45: =SUMIFS('Google data'!$I$3:$I$20000,'Google data'!$A$3:$A$20000,">="&$B45,'Google data'!$A$3:$A$20000,"<="&$C45,'Google data'!$G$3:$G$20000,"<>Month total") -> 0 | F45: =SUMIFS('ChatGPT data'!$I$3:$I$20000,'ChatGPT data'!$A$3:$A$20000,">="&$B45,'ChatGPT data'!$A$3:$A$20000,"<="&$C45,'ChatGPT data'!$G$3:$G$20000,"<>Month total") -> 0 | G45: =SUMIFS('LinkedIn data'!$I$3:$I$20000,'LinkedIn data'!$A$3:$A$20000,">="&$B45,'LinkedIn data'!$A$3:$A$20000,"<="&$C45,'LinkedIn data'!$G$3:$G$20000,"<>Month total") -> 0 | H45: =SUM(D45:G45) -> 0 | I45: =D45*(Settings!$C$22="Yes")+E45*(Settings!$C$23="Yes")+F45*(Settings!$C$24="Yes")+G45*(Settings!$C$25="Yes") -> 0 | J45: =Settings!$D$16*MAX(0,MIN(C45,Settings!$C$11)-MAX(B45,Settings!$C$10)+1)/(Settings!$C$11-Settings!$C$10+1) -> 5753.4247 | K45: =IF(OR(C45>$C$3,I45=0),"",I45-J45) | L45: =SUMIFS('Meta data'!$F$3:$F$20000,'Meta data'!$A$3:$A$20000,">="&$B45,'Meta data'!$A$3:$A$20000,"<="&$C45,'Meta data'!$G$3:$G$20000,"<>Month total") -> 0 | M45: =IF(L45=0,"",D45/L45) | N45: =SUMIFS('Google data'!$F$3:$F$20000,'Google data'!$A$3:$A$20000,">="&$B45,'Google data'!$A$3:$A$20000,"<="&$C45,'Google data'!$G$3:$G$20000,"<>Month total") -> 0 | O45: =IF(N45=0,"",E45/N45) | R45: Agency: Google CPL fell to €27.75. Plan: check channel vs HubSpot discrepancy, pause PP-266, judge case-study statics launched 8 Oct. | S45: =TEXT(B45,"d mmm") -> 5 Oct
A46: 42 | B46: =Settings!$C$13+7*(A46-1) -> 46307 | C46: =B46+6 -> 46313 | D46: =SUMIFS('Meta data'!$I$3:$I$20000,'Meta data'!$A$3:$A$20000,">="&$B46,'Meta data'!$A$3:$A$20000,"<="&$C46,'Meta data'!$G$3:$G$20000,"<>Month total") -> 0 | E46: =SUMIFS('Google data'!$I$3:$I$20000,'Google data'!$A$3:$A$20000,">="&$B46,'Google data'!$A$3:$A$20000,"<="&$C46,'Google data'!$G$3:$G$20000,"<>Month total") -> 0 | F46: =SUMIFS('ChatGPT data'!$I$3:$I$20000,'ChatGPT data'!$A$3:$A$20000,">="&$B46,'ChatGPT data'!$A$3:$A$20000,"<="&$C46,'ChatGPT data'!$G$3:$G$20000,"<>Month total") -> 0 | G46: =SUMIFS('LinkedIn data'!$I$3:$I$20000,'LinkedIn data'!$A$3:$A$20000,">="&$B46,'LinkedIn data'!$A$3:$A$20000,"<="&$C46,'LinkedIn data'!$G$3:$G$20000,"<>Month total") -> 0 | H46: =SUM(D46:G46) -> 0 | I46: =D46*(Settings!$C$22="Yes")+E46*(Settings!$C$23="Yes")+F46*(Settings!$C$24="Yes")+G46*(Settings!$C$25="Yes") -> 0 | J46: =Settings!$D$16*MAX(0,MIN(C46,Settings!$C$11)-MAX(B46,Settings!$C$10)+1)/(Settings!$C$11-Settings!$C$10+1) -> 5753.4247 | K46: =IF(OR(C46>$C$3,I46=0),"",I46-J46) | L46: =SUMIFS('Meta data'!$F$3:$F$20000,'Meta data'!$A$3:$A$20000,">="&$B46,'Meta data'!$A$3:$A$20000,"<="&$C46,'Meta data'!$G$3:$G$20000,"<>Month total") -> 0 | M46: =IF(L46=0,"",D46/L46) | N46: =SUMIFS('Google data'!$F$3:$F$20000,'Google data'!$A$3:$A$20000,">="&$B46,'Google data'!$A$3:$A$20000,"<="&$C46,'Google data'!$G$3:$G$20000,"<>Month total") -> 0 | O46: =IF(N46=0,"",E46/N46) | S46: =TEXT(B46,"d mmm") -> 12 Oct
A47: 43 | B47: =Settings!$C$13+7*(A47-1) -> 46314 | C47: =B47+6 -> 46320 | D47: =SUMIFS('Meta data'!$I$3:$I$20000,'Meta data'!$A$3:$A$20000,">="&$B47,'Meta data'!$A$3:$A$20000,"<="&$C47,'Meta data'!$G$3:$G$20000,"<>Month total") -> 0 | E47: =SUMIFS('Google data'!$I$3:$I$20000,'Google data'!$A$3:$A$20000,">="&$B47,'Google data'!$A$3:$A$20000,"<="&$C47,'Google data'!$G$3:$G$20000,"<>Month total") -> 0 | F47: =SUMIFS('ChatGPT data'!$I$3:$I$20000,'ChatGPT data'!$A$3:$A$20000,">="&$B47,'ChatGPT data'!$A$3:$A$20000,"<="&$C47,'ChatGPT data'!$G$3:$G$20000,"<>Month total") -> 0 | G47: =SUMIFS('LinkedIn data'!$I$3:$I$20000,'LinkedIn data'!$A$3:$A$20000,">="&$B47,'LinkedIn data'!$A$3:$A$20000,"<="&$C47,'LinkedIn data'!$G$3:$G$20000,"<>Month total") -> 0 | H47: =SUM(D47:G47) -> 0 | I47: =D47*(Settings!$C$22="Yes")+E47*(Settings!$C$23="Yes")+F47*(Settings!$C$24="Yes")+G47*(Settings!$C$25="Yes") -> 0 | J47: =Settings!$D$16*MAX(0,MIN(C47,Settings!$C$11)-MAX(B47,Settings!$C$10)+1)/(Settings!$C$11-Settings!$C$10+1) -> 5753.4247 | K47: =IF(OR(C47>$C$3,I47=0),"",I47-J47) | L47: =SUMIFS('Meta data'!$F$3:$F$20000,'Meta data'!$A$3:$A$20000,">="&$B47,'Meta data'!$A$3:$A$20000,"<="&$C47,'Meta data'!$G$3:$G$20000,"<>Month total") -> 0 | M47: =IF(L47=0,"",D47/L47) | N47: =SUMIFS('Google data'!$F$3:$F$20000,'Google data'!$A$3:$A$20000,">="&$B47,'Google data'!$A$3:$A$20000,"<="&$C47,'Google data'!$G$3:$G$20000,"<>Month total") -> 0 | O47: =IF(N47=0,"",E47/N47) | S47: =TEXT(B47,"d mmm") -> 19 Oct
A48: 44 | B48: =Settings!$C$13+7*(A48-1) -> 46321 | C48: =B48+6 -> 46327 | D48: =SUMIFS('Meta data'!$I$3:$I$20000,'Meta data'!$A$3:$A$20000,">="&$B48,'Meta data'!$A$3:$A$20000,"<="&$C48,'Meta data'!$G$3:$G$20000,"<>Month total") -> 0 | E48: =SUMIFS('Google data'!$I$3:$I$20000,'Google data'!$A$3:$A$20000,">="&$B48,'Google data'!$A$3:$A$20000,"<="&$C48,'Google data'!$G$3:$G$20000,"<>Month total") -> 0 | F48: =SUMIFS('ChatGPT data'!$I$3:$I$20000,'ChatGPT data'!$A$3:$A$20000,">="&$B48,'ChatGPT data'!$A$3:$A$20000,"<="&$C48,'ChatGPT data'!$G$3:$G$20000,"<>Month total") -> 0 | G48: =SUMIFS('LinkedIn data'!$I$3:$I$20000,'LinkedIn data'!$A$3:$A$20000,">="&$B48,'LinkedIn data'!$A$3:$A$20000,"<="&$C48,'LinkedIn data'!$G$3:$G$20000,"<>Month total") -> 0 | H48: =SUM(D48:G48) -> 0 | I48: =D48*(Settings!$C$22="Yes")+E48*(Settings!$C$23="Yes")+F48*(Settings!$C$24="Yes")+G48*(Settings!$C$25="Yes") -> 0 | J48: =Settings!$D$16*MAX(0,MIN(C48,Settings!$C$11)-MAX(B48,Settings!$C$10)+1)/(Settings!$C$11-Settings!$C$10+1) -> 5753.4247 | K48: =IF(OR(C48>$C$3,I48=0),"",I48-J48) | L48: =SUMIFS('Meta data'!$F$3:$F$20000,'Meta data'!$A$3:$A$20000,">="&$B48,'Meta data'!$A$3:$A$20000,"<="&$C48,'Meta data'!$G$3:$G$20000,"<>Month total") -> 0 | M48: =IF(L48=0,"",D48/L48) | N48: =SUMIFS('Google data'!$F$3:$F$20000,'Google data'!$A$3:$A$20000,">="&$B48,'Google data'!$A$3:$A$20000,"<="&$C48,'Google data'!$G$3:$G$20000,"<>Month total") -> 0 | O48: =IF(N48=0,"",E48/N48) | S48: =TEXT(B48,"d mmm") -> 26 Oct
A49: 45 | B49: =Settings!$C$13+7*(A49-1) -> 46328 | C49: =B49+6 -> 46334 | D49: =SUMIFS('Meta data'!$I$3:$I$20000,'Meta data'!$A$3:$A$20000,">="&$B49,'Meta data'!$A$3:$A$20000,"<="&$C49,'Meta data'!$G$3:$G$20000,"<>Month total") -> 0 | E49: =SUMIFS('Google data'!$I$3:$I$20000,'Google data'!$A$3:$A$20000,">="&$B49,'Google data'!$A$3:$A$20000,"<="&$C49,'Google data'!$G$3:$G$20000,"<>Month total") -> 0 | F49: =SUMIFS('ChatGPT data'!$I$3:$I$20000,'ChatGPT data'!$A$3:$A$20000,">="&$B49,'ChatGPT data'!$A$3:$A$20000,"<="&$C49,'ChatGPT data'!$G$3:$G$20000,"<>Month total") -> 0 | G49: =SUMIFS('LinkedIn data'!$I$3:$I$20000,'LinkedIn data'!$A$3:$A$20000,">="&$B49,'LinkedIn data'!$A$3:$A$20000,"<="&$C49,'LinkedIn data'!$G$3:$G$20000,"<>Month total") -> 0 | H49: =SUM(D49:G49) -> 0 | I49: =D49*(Settings!$C$22="Yes")+E49*(Settings!$C$23="Yes")+F49*(Settings!$C$24="Yes")+G49*(Settings!$C$25="Yes") -> 0 | J49: =Settings!$D$16*MAX(0,MIN(C49,Settings!$C$11)-MAX(B49,Settings!$C$10)+1)/(Settings!$C$11-Settings!$C$10+1) -> 5753.4247 | K49: =IF(OR(C49>$C$3,I49=0),"",I49-J49) | L49: =SUMIFS('Meta data'!$F$3:$F$20000,'Meta data'!$A$3:$A$20000,">="&$B49,'Meta data'!$A$3:$A$20000,"<="&$C49,'Meta data'!$G$3:$G$20000,"<>Month total") -> 0 | M49: =IF(L49=0,"",D49/L49) | N49: =SUMIFS('Google data'!$F$3:$F$20000,'Google data'!$A$3:$A$20000,">="&$B49,'Google data'!$A$3:$A$20000,"<="&$C49,'Google data'!$G$3:$G$20000,"<>Month total") -> 0 | O49: =IF(N49=0,"",E49/N49) | S49: =TEXT(B49,"d mmm") -> 2 Nov
A50: 46 | B50: =Settings!$C$13+7*(A50-1) -> 46335 | C50: =B50+6 -> 46341 | D50: =SUMIFS('Meta data'!$I$3:$I$20000,'Meta data'!$A$3:$A$20000,">="&$B50,'Meta data'!$A$3:$A$20000,"<="&$C50,'Meta data'!$G$3:$G$20000,"<>Month total") -> 0 | E50: =SUMIFS('Google data'!$I$3:$I$20000,'Google data'!$A$3:$A$20000,">="&$B50,'Google data'!$A$3:$A$20000,"<="&$C50,'Google data'!$G$3:$G$20000,"<>Month total") -> 0 | F50: =SUMIFS('ChatGPT data'!$I$3:$I$20000,'ChatGPT data'!$A$3:$A$20000,">="&$B50,'ChatGPT data'!$A$3:$A$20000,"<="&$C50,'ChatGPT data'!$G$3:$G$20000,"<>Month total") -> 0 | G50: =SUMIFS('LinkedIn data'!$I$3:$I$20000,'LinkedIn data'!$A$3:$A$20000,">="&$B50,'LinkedIn data'!$A$3:$A$20000,"<="&$C50,'LinkedIn data'!$G$3:$G$20000,"<>Month total") -> 0 | H50: =SUM(D50:G50) -> 0 | I50: =D50*(Settings!$C$22="Yes")+E50*(Settings!$C$23="Yes")+F50*(Settings!$C$24="Yes")+G50*(Settings!$C$25="Yes") -> 0 | J50: =Settings!$D$16*MAX(0,MIN(C50,Settings!$C$11)-MAX(B50,Settings!$C$10)+1)/(Settings!$C$11-Settings!$C$10+1) -> 5753.4247 | K50: =IF(OR(C50>$C$3,I50=0),"",I50-J50) | L50: =SUMIFS('Meta data'!$F$3:$F$20000,'Meta data'!$A$3:$A$20000,">="&$B50,'Meta data'!$A$3:$A$20000,"<="&$C50,'Meta data'!$G$3:$G$20000,"<>Month total") -> 0 | M50: =IF(L50=0,"",D50/L50) | N50: =SUMIFS('Google data'!$F$3:$F$20000,'Google data'!$A$3:$A$20000,">="&$B50,'Google data'!$A$3:$A$20000,"<="&$C50,'Google data'!$G$3:$G$20000,"<>Month total") -> 0 | O50: =IF(N50=0,"",E50/N50) | S50: =TEXT(B50,"d mmm") -> 9 Nov
A51: 47 | B51: =Settings!$C$13+7*(A51-1) -> 46342 | C51: =B51+6 -> 46348 | D51: =SUMIFS('Meta data'!$I$3:$I$20000,'Meta data'!$A$3:$A$20000,">="&$B51,'Meta data'!$A$3:$A$20000,"<="&$C51,'Meta data'!$G$3:$G$20000,"<>Month total") -> 0 | E51: =SUMIFS('Google data'!$I$3:$I$20000,'Google data'!$A$3:$A$20000,">="&$B51,'Google data'!$A$3:$A$20000,"<="&$C51,'Google data'!$G$3:$G$20000,"<>Month total") -> 0 | F51: =SUMIFS('ChatGPT data'!$I$3:$I$20000,'ChatGPT data'!$A$3:$A$20000,">="&$B51,'ChatGPT data'!$A$3:$A$20000,"<="&$C51,'ChatGPT data'!$G$3:$G$20000,"<>Month total") -> 0 | G51: =SUMIFS('LinkedIn data'!$I$3:$I$20000,'LinkedIn data'!$A$3:$A$20000,">="&$B51,'LinkedIn data'!$A$3:$A$20000,"<="&$C51,'LinkedIn data'!$G$3:$G$20000,"<>Month total") -> 0 | H51: =SUM(D51:G51) -> 0 | I51: =D51*(Settings!$C$22="Yes")+E51*(Settings!$C$23="Yes")+F51*(Settings!$C$24="Yes")+G51*(Settings!$C$25="Yes") -> 0 | J51: =Settings!$D$16*MAX(0,MIN(C51,Settings!$C$11)-MAX(B51,Settings!$C$10)+1)/(Settings!$C$11-Settings!$C$10+1) -> 5753.4247 | K51: =IF(OR(C51>$C$3,I51=0),"",I51-J51) | L51: =SUMIFS('Meta data'!$F$3:$F$20000,'Meta data'!$A$3:$A$20000,">="&$B51,'Meta data'!$A$3:$A$20000,"<="&$C51,'Meta data'!$G$3:$G$20000,"<>Month total") -> 0 | M51: =IF(L51=0,"",D51/L51) | N51: =SUMIFS('Google data'!$F$3:$F$20000,'Google data'!$A$3:$A$20000,">="&$B51,'Google data'!$A$3:$A$20000,"<="&$C51,'Google data'!$G$3:$G$20000,"<>Month total") -> 0 | O51: =IF(N51=0,"",E51/N51) | S51: =TEXT(B51,"d mmm") -> 16 Nov
A52: 48 | B52: =Settings!$C$13+7*(A52-1) -> 46349 | C52: =B52+6 -> 46355 | D52: =SUMIFS('Meta data'!$I$3:$I$20000,'Meta data'!$A$3:$A$20000,">="&$B52,'Meta data'!$A$3:$A$20000,"<="&$C52,'Meta data'!$G$3:$G$20000,"<>Month total") -> 0 | E52: =SUMIFS('Google data'!$I$3:$I$20000,'Google data'!$A$3:$A$20000,">="&$B52,'Google data'!$A$3:$A$20000,"<="&$C52,'Google data'!$G$3:$G$20000,"<>Month total") -> 0 | F52: =SUMIFS('ChatGPT data'!$I$3:$I$20000,'ChatGPT data'!$A$3:$A$20000,">="&$B52,'ChatGPT data'!$A$3:$A$20000,"<="&$C52,'ChatGPT data'!$G$3:$G$20000,"<>Month total") -> 0 | G52: =SUMIFS('LinkedIn data'!$I$3:$I$20000,'LinkedIn data'!$A$3:$A$20000,">="&$B52,'LinkedIn data'!$A$3:$A$20000,"<="&$C52,'LinkedIn data'!$G$3:$G$20000,"<>Month total") -> 0 | H52: =SUM(D52:G52) -> 0 | I52: =D52*(Settings!$C$22="Yes")+E52*(Settings!$C$23="Yes")+F52*(Settings!$C$24="Yes")+G52*(Settings!$C$25="Yes") -> 0 | J52: =Settings!$D$16*MAX(0,MIN(C52,Settings!$C$11)-MAX(B52,Settings!$C$10)+1)/(Settings!$C$11-Settings!$C$10+1) -> 5753.4247 | K52: =IF(OR(C52>$C$3,I52=0),"",I52-J52) | L52: =SUMIFS('Meta data'!$F$3:$F$20000,'Meta data'!$A$3:$A$20000,">="&$B52,'Meta data'!$A$3:$A$20000,"<="&$C52,'Meta data'!$G$3:$G$20000,"<>Month total") -> 0 | M52: =IF(L52=0,"",D52/L52) | N52: =SUMIFS('Google data'!$F$3:$F$20000,'Google data'!$A$3:$A$20000,">="&$B52,'Google data'!$A$3:$A$20000,"<="&$C52,'Google data'!$G$3:$G$20000,"<>Month total") -> 0 | O52: =IF(N52=0,"",E52/N52) | S52: =TEXT(B52,"d mmm") -> 23 Nov
A53: 49 | B53: =Settings!$C$13+7*(A53-1) -> 46356 | C53: =B53+6 -> 46362 | D53: =SUMIFS('Meta data'!$I$3:$I$20000,'Meta data'!$A$3:$A$20000,">="&$B53,'Meta data'!$A$3:$A$20000,"<="&$C53,'Meta data'!$G$3:$G$20000,"<>Month total") -> 0 | E53: =SUMIFS('Google data'!$I$3:$I$20000,'Google data'!$A$3:$A$20000,">="&$B53,'Google data'!$A$3:$A$20000,"<="&$C53,'Google data'!$G$3:$G$20000,"<>Month total") -> 0 | F53: =SUMIFS('ChatGPT data'!$I$3:$I$20000,'ChatGPT data'!$A$3:$A$20000,">="&$B53,'ChatGPT data'!$A$3:$A$20000,"<="&$C53,'ChatGPT data'!$G$3:$G$20000,"<>Month total") -> 0 | G53: =SUMIFS('LinkedIn data'!$I$3:$I$20000,'LinkedIn data'!$A$3:$A$20000,">="&$B53,'LinkedIn data'!$A$3:$A$20000,"<="&$C53,'LinkedIn data'!$G$3:$G$20000,"<>Month total") -> 0 | H53: =SUM(D53:G53) -> 0 | I53: =D53*(Settings!$C$22="Yes")+E53*(Settings!$C$23="Yes")+F53*(Settings!$C$24="Yes")+G53*(Settings!$C$25="Yes") -> 0 | J53: =Settings!$D$16*MAX(0,MIN(C53,Settings!$C$11)-MAX(B53,Settings!$C$10)+1)/(Settings!$C$11-Settings!$C$10+1) -> 5753.4247 | K53: =IF(OR(C53>$C$3,I53=0),"",I53-J53) | L53: =SUMIFS('Meta data'!$F$3:$F$20000,'Meta data'!$A$3:$A$20000,">="&$B53,'Meta data'!$A$3:$A$20000,"<="&$C53,'Meta data'!$G$3:$G$20000,"<>Month total") -> 0 | M53: =IF(L53=0,"",D53/L53) | N53: =SUMIFS('Google data'!$F$3:$F$20000,'Google data'!$A$3:$A$20000,">="&$B53,'Google data'!$A$3:$A$20000,"<="&$C53,'Google data'!$G$3:$G$20000,"<>Month total") -> 0 | O53: =IF(N53=0,"",E53/N53) | S53: =TEXT(B53,"d mmm") -> 30 Nov
A54: 50 | B54: =Settings!$C$13+7*(A54-1) -> 46363 | C54: =B54+6 -> 46369 | D54: =SUMIFS('Meta data'!$I$3:$I$20000,'Meta data'!$A$3:$A$20000,">="&$B54,'Meta data'!$A$3:$A$20000,"<="&$C54,'Meta data'!$G$3:$G$20000,"<>Month total") -> 0 | E54: =SUMIFS('Google data'!$I$3:$I$20000,'Google data'!$A$3:$A$20000,">="&$B54,'Google data'!$A$3:$A$20000,"<="&$C54,'Google data'!$G$3:$G$20000,"<>Month total") -> 0 | F54: =SUMIFS('ChatGPT data'!$I$3:$I$20000,'ChatGPT data'!$A$3:$A$20000,">="&$B54,'ChatGPT data'!$A$3:$A$20000,"<="&$C54,'ChatGPT data'!$G$3:$G$20000,"<>Month total") -> 0 | G54: =SUMIFS('LinkedIn data'!$I$3:$I$20000,'LinkedIn data'!$A$3:$A$20000,">="&$B54,'LinkedIn data'!$A$3:$A$20000,"<="&$C54,'LinkedIn data'!$G$3:$G$20000,"<>Month total") -> 0 | H54: =SUM(D54:G54) -> 0 | I54: =D54*(Settings!$C$22="Yes")+E54*(Settings!$C$23="Yes")+F54*(Settings!$C$24="Yes")+G54*(Settings!$C$25="Yes") -> 0 | J54: =Settings!$D$16*MAX(0,MIN(C54,Settings!$C$11)-MAX(B54,Settings!$C$10)+1)/(Settings!$C$11-Settings!$C$10+1) -> 5753.4247 | K54: =IF(OR(C54>$C$3,I54=0),"",I54-J54) | L54: =SUMIFS('Meta data'!$F$3:$F$20000,'Meta data'!$A$3:$A$20000,">="&$B54,'Meta data'!$A$3:$A$20000,"<="&$C54,'Meta data'!$G$3:$G$20000,"<>Month total") -> 0 | M54: =IF(L54=0,"",D54/L54) | N54: =SUMIFS('Google data'!$F$3:$F$20000,'Google data'!$A$3:$A$20000,">="&$B54,'Google data'!$A$3:$A$20000,"<="&$C54,'Google data'!$G$3:$G$20000,"<>Month total") -> 0 | O54: =IF(N54=0,"",E54/N54) | S54: =TEXT(B54,"d mmm") -> 7 Dec
A55: 51 | B55: =Settings!$C$13+7*(A55-1) -> 46370 | C55: =B55+6 -> 46376 | D55: =SUMIFS('Meta data'!$I$3:$I$20000,'Meta data'!$A$3:$A$20000,">="&$B55,'Meta data'!$A$3:$A$20000,"<="&$C55,'Meta data'!$G$3:$G$20000,"<>Month total") -> 0 | E55: =SUMIFS('Google data'!$I$3:$I$20000,'Google data'!$A$3:$A$20000,">="&$B55,'Google data'!$A$3:$A$20000,"<="&$C55,'Google data'!$G$3:$G$20000,"<>Month total") -> 0 | F55: =SUMIFS('ChatGPT data'!$I$3:$I$20000,'ChatGPT data'!$A$3:$A$20000,">="&$B55,'ChatGPT data'!$A$3:$A$20000,"<="&$C55,'ChatGPT data'!$G$3:$G$20000,"<>Month total") -> 0 | G55: =SUMIFS('LinkedIn data'!$I$3:$I$20000,'LinkedIn data'!$A$3:$A$20000,">="&$B55,'LinkedIn data'!$A$3:$A$20000,"<="&$C55,'LinkedIn data'!$G$3:$G$20000,"<>Month total") -> 0 | H55: =SUM(D55:G55) -> 0 | I55: =D55*(Settings!$C$22="Yes")+E55*(Settings!$C$23="Yes")+F55*(Settings!$C$24="Yes")+G55*(Settings!$C$25="Yes") -> 0 | J55: =Settings!$D$16*MAX(0,MIN(C55,Settings!$C$11)-MAX(B55,Settings!$C$10)+1)/(Settings!$C$11-Settings!$C$10+1) -> 5753.4247 | K55: =IF(OR(C55>$C$3,I55=0),"",I55-J55) | L55: =SUMIFS('Meta data'!$F$3:$F$20000,'Meta data'!$A$3:$A$20000,">="&$B55,'Meta data'!$A$3:$A$20000,"<="&$C55,'Meta data'!$G$3:$G$20000,"<>Month total") -> 0 | M55: =IF(L55=0,"",D55/L55) | N55: =SUMIFS('Google data'!$F$3:$F$20000,'Google data'!$A$3:$A$20000,">="&$B55,'Google data'!$A$3:$A$20000,"<="&$C55,'Google data'!$G$3:$G$20000,"<>Month total") -> 0 | O55: =IF(N55=0,"",E55/N55) | S55: =TEXT(B55,"d mmm") -> 14 Dec
A56: 52 | B56: =Settings!$C$13+7*(A56-1) -> 46377 | C56: =B56+6 -> 46383 | D56: =SUMIFS('Meta data'!$I$3:$I$20000,'Meta data'!$A$3:$A$20000,">="&$B56,'Meta data'!$A$3:$A$20000,"<="&$C56,'Meta data'!$G$3:$G$20000,"<>Month total") -> 0 | E56: =SUMIFS('Google data'!$I$3:$I$20000,'Google data'!$A$3:$A$20000,">="&$B56,'Google data'!$A$3:$A$20000,"<="&$C56,'Google data'!$G$3:$G$20000,"<>Month total") -> 0 | F56: =SUMIFS('ChatGPT data'!$I$3:$I$20000,'ChatGPT data'!$A$3:$A$20000,">="&$B56,'ChatGPT data'!$A$3:$A$20000,"<="&$C56,'ChatGPT data'!$G$3:$G$20000,"<>Month total") -> 0 | G56: =SUMIFS('LinkedIn data'!$I$3:$I$20000,'LinkedIn data'!$A$3:$A$20000,">="&$B56,'LinkedIn data'!$A$3:$A$20000,"<="&$C56,'LinkedIn data'!$G$3:$G$20000,"<>Month total") -> 0 | H56: =SUM(D56:G56) -> 0 | I56: =D56*(Settings!$C$22="Yes")+E56*(Settings!$C$23="Yes")+F56*(Settings!$C$24="Yes")+G56*(Settings!$C$25="Yes") -> 0 | J56: =Settings!$D$16*MAX(0,MIN(C56,Settings!$C$11)-MAX(B56,Settings!$C$10)+1)/(Settings!$C$11-Settings!$C$10+1) -> 5753.4247 | K56: =IF(OR(C56>$C$3,I56=0),"",I56-J56) | L56: =SUMIFS('Meta data'!$F$3:$F$20000,'Meta data'!$A$3:$A$20000,">="&$B56,'Meta data'!$A$3:$A$20000,"<="&$C56,'Meta data'!$G$3:$G$20000,"<>Month total") -> 0 | M56: =IF(L56=0,"",D56/L56) | N56: =SUMIFS('Google data'!$F$3:$F$20000,'Google data'!$A$3:$A$20000,">="&$B56,'Google data'!$A$3:$A$20000,"<="&$C56,'Google data'!$G$3:$G$20000,"<>Month total") -> 0 | O56: =IF(N56=0,"",E56/N56) | S56: =TEXT(B56,"d mmm") -> 21 Dec
A57: 53 | B57: =Settings!$C$13+7*(A57-1) -> 46384 | C57: =B57+6 -> 46390 | D57: =SUMIFS('Meta data'!$I$3:$I$20000,'Meta data'!$A$3:$A$20000,">="&$B57,'Meta data'!$A$3:$A$20000,"<="&$C57,'Meta data'!$G$3:$G$20000,"<>Month total") -> 0 | E57: =SUMIFS('Google data'!$I$3:$I$20000,'Google data'!$A$3:$A$20000,">="&$B57,'Google data'!$A$3:$A$20000,"<="&$C57,'Google data'!$G$3:$G$20000,"<>Month total") -> 0 | F57: =SUMIFS('ChatGPT data'!$I$3:$I$20000,'ChatGPT data'!$A$3:$A$20000,">="&$B57,'ChatGPT data'!$A$3:$A$20000,"<="&$C57,'ChatGPT data'!$G$3:$G$20000,"<>Month total") -> 0 | G57: =SUMIFS('LinkedIn data'!$I$3:$I$20000,'LinkedIn data'!$A$3:$A$20000,">="&$B57,'LinkedIn data'!$A$3:$A$20000,"<="&$C57,'LinkedIn data'!$G$3:$G$20000,"<>Month total") -> 0 | H57: =SUM(D57:G57) -> 0 | I57: =D57*(Settings!$C$22="Yes")+E57*(Settings!$C$23="Yes")+F57*(Settings!$C$24="Yes")+G57*(Settings!$C$25="Yes") -> 0 | J57: =Settings!$D$16*MAX(0,MIN(C57,Settings!$C$11)-MAX(B57,Settings!$C$10)+1)/(Settings!$C$11-Settings!$C$10+1) -> 3287.6712 | K57: =IF(OR(C57>$C$3,I57=0),"",I57-J57) | L57: =SUMIFS('Meta data'!$F$3:$F$20000,'Meta data'!$A$3:$A$20000,">="&$B57,'Meta data'!$A$3:$A$20000,"<="&$C57,'Meta data'!$G$3:$G$20000,"<>Month total") -> 0 | M57: =IF(L57=0,"",D57/L57) | N57: =SUMIFS('Google data'!$F$3:$F$20000,'Google data'!$A$3:$A$20000,">="&$B57,'Google data'!$A$3:$A$20000,"<="&$C57,'Google data'!$G$3:$G$20000,"<>Month total") -> 0 | O57: =IF(N57=0,"",E57/N57) | S57: =TEXT(B57,"d mmm") -> 28 Dec
A59: Week 1 includes the last days of the previous year. Over/under plan is shown for complete weeks with data. Notes marked 'Agency:' are summarised from the agency's weekly reports.
A61: WEEKLY SPEND BY CHANNEL (platform data)

Sheet Monthly
A1: Monthly spend
A2: ="Amounts in "&Settings!$C$6&" · Google converted from EUR with the Settings rates · platform data up to "&TEXT(Settings!$C$5,"d mmm yyyy") -> Amounts in USD · Google converted from EUR with the Settings rates · platform data up to 30 Sep 2026 | T2: Data up to | U2: =Settings!$C$5 -> 46295
A4: Month | B4: Quarter | C4: Meta | D4: Google Ads | E4: ChatGPT Ads | F4: LinkedIn Ads | G4: Total – all channels | H4: Counts toward budget | I4: Plan (budget spread evenly by day) | J4: Over (+) / under (−) plan | K4: Cumulative spend (budget channels) | L4: Cumulative plan | M4: Maximum | N4: % of budget used | O4: Status | P4: Meta as billed (USD) | Q4: Google as billed (EUR) | R4: EUR → USD rate used | S4: Chart label
A5: =DATE(Settings!$C$12,1,1) -> 46023 | B5: ="Q"&ROUNDUP(MONTH(A5)/3,0) -> Q1 | C5: =SUMIFS('Meta data'!$I$3:$I$20000,'Meta data'!$A$3:$A$20000,">="&$A5,'Meta data'!$A$3:$A$20000,"<="&EOMONTH($A5,0)) -> 8092.51 | D5: =SUMIFS('Google data'!$I$3:$I$20000,'Google data'!$A$3:$A$20000,">="&$A5,'Google data'!$A$3:$A$20000,"<="&EOMONTH($A5,0)) -> 10838.862 | E5: =SUMIFS('ChatGPT data'!$I$3:$I$20000,'ChatGPT data'!$A$3:$A$20000,">="&$A5,'ChatGPT data'!$A$3:$A$20000,"<="&EOMONTH($A5,0)) -> 0 | F5: =SUMIFS('LinkedIn data'!$I$3:$I$20000,'LinkedIn data'!$A$3:$A$20000,">="&$A5,'LinkedIn data'!$A$3:$A$20000,"<="&EOMONTH($A5,0)) -> 0 | G5: =SUM(C5:F5) -> 18931.372 | H5: =C5*(Settings!$C$22="Yes")+D5*(Settings!$C$23="Yes")+E5*(Settings!$C$24="Yes")+F5*(Settings!$C$25="Yes") -> 18931.372 | I5: =Settings!$D$16*MAX(0,MIN(EOMONTH($A5,0),Settings!$C$11)-MAX($A5,Settings!$C$10)+1)/(Settings!$C$11-Settings!$C$10+1) -> 25479.452 | J5: =IF(EOMONTH($A5,0)>Settings!$C$5,"",H5-I5) -> -6548.0798 | K5: =IF($A5>Settings!$C$5,"",SUM($H$5:H5)) -> 18931.372 | L5: =SUM($I$5:I5) -> 25479.452 | M5: =Settings!$D$17 -> 320000 | N5: =IF(OR(K5="",Settings!$D$16=0),"",K5/Settings!$D$16) -> 0.063104574 | O5: =IF(EOMONTH($A5,0)<=Settings!$C$5,"Complete",IF($A5<=Settings!$C$5,"In progress","Not started")) -> Complete | P5: =SUMIFS('Meta data'!$C$3:$C$20000,'Meta data'!$A$3:$A$20000,">="&$A5,'Meta data'!$A$3:$A$20000,"<="&EOMONTH($A5,0)) -> 8092.51 | Q5: =SUMIFS('Google data'!$C$3:$C$20000,'Google data'!$A$3:$A$20000,">="&$A5,'Google data'!$A$3:$A$20000,"<="&EOMONTH($A5,0)) -> 9697.47 | R5: =INDEX(Settings!$B$29:$B$40,MONTH(A5)) -> 1.1177 | S5: =TEXT(A5,"mmm") -> Jan
A6: =DATE(Settings!$C$12,2,1) -> 46054 | B6: ="Q"&ROUNDUP(MONTH(A6)/3,0) -> Q1 | C6: =SUMIFS('Meta data'!$I$3:$I$20000,'Meta data'!$A$3:$A$20000,">="&$A6,'Meta data'!$A$3:$A$20000,"<="&EOMONTH($A6,0)) -> 28952.75 | D6: =SUMIFS('Google data'!$I$3:$I$20000,'Google data'!$A$3:$A$20000,">="&$A6,'Google data'!$A$3:$A$20000,"<="&EOMONTH($A6,0)) -> 11084.41 | E6: =SUMIFS('ChatGPT data'!$I$3:$I$20000,'ChatGPT data'!$A$3:$A$20000,">="&$A6,'ChatGPT data'!$A$3:$A$20000,"<="&EOMONTH($A6,0)) -> 0 | F6: =SUMIFS('LinkedIn data'!$I$3:$I$20000,'LinkedIn data'!$A$3:$A$20000,">="&$A6,'LinkedIn data'!$A$3:$A$20000,"<="&EOMONTH($A6,0)) -> 0 | G6: =SUM(C6:F6) -> 40037.16 | H6: =C6*(Settings!$C$22="Yes")+D6*(Settings!$C$23="Yes")+E6*(Settings!$C$24="Yes")+F6*(Settings!$C$25="Yes") -> 40037.16 | I6: =Settings!$D$16*MAX(0,MIN(EOMONTH($A6,0),Settings!$C$11)-MAX($A6,Settings!$C$10)+1)/(Settings!$C$11-Settings!$C$10+1) -> 23013.699 | J6: =IF(EOMONTH($A6,0)>Settings!$C$5,"",H6-I6) -> 17023.461 | K6: =IF($A6>Settings!$C$5,"",SUM($H$5:H6)) -> 58968.532 | L6: =SUM($I$5:I6) -> 48493.151 | M6: =Settings!$D$17 -> 320000 | N6: =IF(OR(K6="",Settings!$D$16=0),"",K6/Settings!$D$16) -> 0.19656177 | O6: =IF(EOMONTH($A6,0)<=Settings!$C$5,"Complete",IF($A6<=Settings!$C$5,"In progress","Not started")) -> Complete | P6: =SUMIFS('Meta data'!$C$3:$C$20000,'Meta data'!$A$3:$A$20000,">="&$A6,'Meta data'!$A$3:$A$20000,"<="&EOMONTH($A6,0)) -> 28952.75 | Q6: =SUMIFS('Google data'!$C$3:$C$20000,'Google data'!$A$3:$A$20000,">="&$A6,'Google data'!$A$3:$A$20000,"<="&EOMONTH($A6,0)) -> 9917.16 | R6: =INDEX(Settings!$B$29:$B$40,MONTH(A6)) -> 1.1177 | S6: =TEXT(A6,"mmm") -> Feb
A7: =DATE(Settings!$C$12,3,1) -> 46082 | B7: ="Q"&ROUNDUP(MONTH(A7)/3,0) -> Q1 | C7: =SUMIFS('Meta data'!$I$3:$I$20000,'Meta data'!$A$3:$A$20000,">="&$A7,'Meta data'!$A$3:$A$20000,"<="&EOMONTH($A7,0)) -> 38386.84 | D7: =SUMIFS('Google data'!$I$3:$I$20000,'Google data'!$A$3:$A$20000,">="&$A7,'Google data'!$A$3:$A$20000,"<="&EOMONTH($A7,0)) -> 10113.218 | E7: =SUMIFS('ChatGPT data'!$I$3:$I$20000,'ChatGPT data'!$A$3:$A$20000,">="&$A7,'ChatGPT data'!$A$3:$A$20000,"<="&EOMONTH($A7,0)) -> 0 | F7: =SUMIFS('LinkedIn data'!$I$3:$I$20000,'LinkedIn data'!$A$3:$A$20000,">="&$A7,'LinkedIn data'!$A$3:$A$20000,"<="&EOMONTH($A7,0)) -> 0 | G7: =SUM(C7:F7) -> 48500.058 | H7: =C7*(Settings!$C$22="Yes")+D7*(Settings!$C$23="Yes")+E7*(Settings!$C$24="Yes")+F7*(Settings!$C$25="Yes") -> 48500.058 | I7: =Settings!$D$16*MAX(0,MIN(EOMONTH($A7,0),Settings!$C$11)-MAX($A7,Settings!$C$10)+1)/(Settings!$C$11-Settings!$C$10+1) -> 25479.452 | J7: =IF(EOMONTH($A7,0)>Settings!$C$5,"",H7-I7) -> 23020.606 | K7: =IF($A7>Settings!$C$5,"",SUM($H$5:H7)) -> 107468.59 | L7: =SUM($I$5:I7) -> 73972.603 | M7: =Settings!$D$17 -> 320000 | N7: =IF(OR(K7="",Settings!$D$16=0),"",K7/Settings!$D$16) -> 0.35822863 | O7: =IF(EOMONTH($A7,0)<=Settings!$C$5,"Complete",IF($A7<=Settings!$C$5,"In progress","Not started")) -> Complete | P7: =SUMIFS('Meta data'!$C$3:$C$20000,'Meta data'!$A$3:$A$20000,">="&$A7,'Meta data'!$A$3:$A$20000,"<="&EOMONTH($A7,0)) -> 38386.84 | Q7: =SUMIFS('Google data'!$C$3:$C$20000,'Google data'!$A$3:$A$20000,">="&$A7,'Google data'!$A$3:$A$20000,"<="&EOMONTH($A7,0)) -> 9048.24 | R7: =INDEX(Settings!$B$29:$B$40,MONTH(A7)) -> 1.1177 | S7: =TEXT(A7,"mmm") -> Mar
A8: =DATE(Settings!$C$12,4,1) -> 46113 | B8: ="Q"&ROUNDUP(MONTH(A8)/3,0) -> Q2 | C8: =SUMIFS('Meta data'!$I$3:$I$20000,'Meta data'!$A$3:$A$20000,">="&$A8,'Meta data'!$A$3:$A$20000,"<="&EOMONTH($A8,0)) -> 22241.56 | D8: =SUMIFS('Google data'!$I$3:$I$20000,'Google data'!$A$3:$A$20000,">="&$A8,'Google data'!$A$3:$A$20000,"<="&EOMONTH($A8,0)) -> 9972.2647 | E8: =SUMIFS('ChatGPT data'!$I$3:$I$20000,'ChatGPT data'!$A$3:$A$20000,">="&$A8,'ChatGPT data'!$A$3:$A$20000,"<="&EOMONTH($A8,0)) -> 0 | F8: =SUMIFS('LinkedIn data'!$I$3:$I$20000,'LinkedIn data'!$A$3:$A$20000,">="&$A8,'LinkedIn data'!$A$3:$A$20000,"<="&EOMONTH($A8,0)) -> 0 | G8: =SUM(C8:F8) -> 32213.825 | H8: =C8*(Settings!$C$22="Yes")+D8*(Settings!$C$23="Yes")+E8*(Settings!$C$24="Yes")+F8*(Settings!$C$25="Yes") -> 32213.825 | I8: =Settings!$D$16*MAX(0,MIN(EOMONTH($A8,0),Settings!$C$11)-MAX($A8,Settings!$C$10)+1)/(Settings!$C$11-Settings!$C$10+1) -> 24657.534 | J8: =IF(EOMONTH($A8,0)>Settings!$C$5,"",H8-I8) -> 7556.2905 | K8: =IF($A8>Settings!$C$5,"",SUM($H$5:H8)) -> 139682.41 | L8: =SUM($I$5:I8) -> 98630.137 | M8: =Settings!$D$17 -> 320000 | N8: =IF(OR(K8="",Settings!$D$16=0),"",K8/Settings!$D$16) -> 0.46560805 | O8: =IF(EOMONTH($A8,0)<=Settings!$C$5,"Complete",IF($A8<=Settings!$C$5,"In progress","Not started")) -> Complete | P8: =SUMIFS('Meta data'!$C$3:$C$20000,'Meta data'!$A$3:$A$20000,">="&$A8,'Meta data'!$A$3:$A$20000,"<="&EOMONTH($A8,0)) -> 22241.56 | Q8: =SUMIFS('Google data'!$C$3:$C$20000,'Google data'!$A$3:$A$20000,">="&$A8,'Google data'!$A$3:$A$20000,"<="&EOMONTH($A8,0)) -> 8922.13 | R8: =INDEX(Settings!$B$29:$B$40,MONTH(A8)) -> 1.1177 | S8: =TEXT(A8,"mmm") -> Apr
