Workbook

Sheet Overview
A1: Plug and Play – Paid Ads Spend Overview 2026
A2: Blue text / yellow cells = inputs you can edit. Black = formulas. Green = pulled from another tab.
A4: 1. Budget inputs
A5: Setting | B5: Value | C5: Note
A6: Meta annual budget | B6: 180000 | C6: Given to Felipe as the 2026 Meta budget.
A7: Google annual budget | B7: 90000 | C7: Given to Felipe as the 2026 Google (Search) budget.
A8: LinkedIn annual budget | B8: 0 | C8: Not live yet. Enter a number if it gets approved.
A9: ChatGPT Ads annual budget | B9: 0 | C9: Enter if ChatGPT Ads has its own budget line.
A10: Stretch total budget (scenario) | B10: 350000 | C10: Possible stretch, still to be decided.
A11: Last month with closed data (1-12) | B11: 9 | C11: 9 = data through end of September. Change when you add October.
A13: 2. Full year 2026: spend vs. budget (year to date)
A14: Platform | B14: Annual budget | C14: YTD spend | D14: Remaining budget | E14: % of budget used | F14: % of year elapsed | G14: Pacing | H14: Avg spend / month so far | I14: Budget left / month (rest of year) | J14: Source of YTD figure
A15: Meta | B15: =$B$6 -> 180000 | C15: =IF(SUMPRODUCT(('Monthly Spend'!$A$6:$A$17<=$B$11)*ISNUMBER('Monthly Spend'!C$6:C$17))>=$B$11,SUMPRODUCT(('Monthly Spend'!$A$6:$A$17<=$B$11)*'Monthly Spend'!C$6:C$17),'By Territory'!B$20) -> 167061.59 | D15: =B15-C15 -> 12938.41 | E15: =IF(B15=0,"n/a",C15/B15) -> 0.92811994 | F15: =$B$11/12 -> 0.75 | G15: =IF(B15=0,IF(C15>0,"Spend with no budget","No budget set"),IF(E15>F15*1.1,"Ahead of pace",IF(E15<F15*0.9,"Behind pace","On pace"))) -> Ahead of pace | H15: =C15/$B$11 -> 18562.399 | I15: =IF($B$11>=12,0,D15/(12-$B$11)) -> 4312.8033 | J15: =IF(SUMPRODUCT(('Monthly Spend'!$A$6:$A$17<=$B$11)*ISNUMBER('Monthly Spend'!C$6:C$17))>=$B$11,"Monthly exports","Territory report (Sep 2026)") -> Territory report (Sep 2026)
A16: Google | B16: =$B$7 -> 90000 | C16: =IF(SUMPRODUCT(('Monthly Spend'!$A$6:$A$17<=$B$11)*ISNUMBER('Monthly Spend'!D$6:D$17))>=$B$11,SUMPRODUCT(('Monthly Spend'!$A$6:$A$17<=$B$11)*'Monthly Spend'!D$6:D$17),'By Territory'!C$20) -> 82856.15 | D16: =B16-C16 -> 7143.85 | E16: =IF(B16=0,"n/a",C16/B16) -> 0.92062389 | F16: =$B$11/12 -> 0.75 | G16: =IF(B16=0,IF(C16>0,"Spend with no budget","No budget set"),IF(E16>F16*1.1,"Ahead of pace",IF(E16<F16*0.9,"Behind pace","On pace"))) -> Ahead of pace | H16: =C16/$B$11 -> 9206.2389 | I16: =IF($B$11>=12,0,D16/(12-$B$11)) -> 2381.2833 | J16: =IF(SUMPRODUCT(('Monthly Spend'!$A$6:$A$17<=$B$11)*ISNUMBER('Monthly Spend'!D$6:D$17))>=$B$11,"Monthly exports","Territory report (Sep 2026)") -> Territory report (Sep 2026)
A17: LinkedIn | B17: =$B$8 -> 0 | C17: =SUMPRODUCT(('Monthly Spend'!$A$6:$A$17<=$B$11)*'Monthly Spend'!E$6:E$17) -> 0 | D17: =B17-C17 -> 0 | E17: =IF(B17=0,"n/a",C17/B17) -> n/a | F17: =$B$11/12 -> 0.75 | G17: =IF(B17=0,IF(C17>0,"Spend with no budget","No budget set"),IF(E17>F17*1.1,"Ahead of pace",IF(E17<F17*0.9,"Behind pace","On pace"))) -> No budget set | H17: =C17/$B$11 -> 0 | I17: =IF($B$11>=12,0,D17/(12-$B$11)) -> 0 | J17: =IF(SUMPRODUCT(('Monthly Spend'!$A$6:$A$17<=$B$11)*ISNUMBER('Monthly Spend'!E$6:E$17))>0,"Monthly exports","No spend entered") -> No spend entered
A18: ChatGPT | B18: =$B$9 -> 0 | C18: =SUMPRODUCT(('Monthly Spend'!$A$6:$A$17<=$B$11)*'Monthly Spend'!F$6:F$17) -> 0 | D18: =B18-C18 -> 0 | E18: =IF(B18=0,"n/a",C18/B18) -> n/a | F18: =$B$11/12 -> 0.75 | G18: =IF(B18=0,IF(C18>0,"Spend with no budget","No budget set"),IF(E18>F18*1.1,"Ahead of pace",IF(E18<F18*0.9,"Behind pace","On pace"))) -> No budget set | H18: =C18/$B$11 -> 0 | I18: =IF($B$11>=12,0,D18/(12-$B$11)) -> 0 | J18: =IF(SUMPRODUCT(('Monthly Spend'!$A$6:$A$17<=$B$11)*ISNUMBER('Monthly Spend'!F$6:F$17))>0,"Monthly exports","No spend entered") -> No spend entered
A19: TOTAL | B19: =SUM(B15:B18) -> 270000 | C19: =SUM(C15:C18) -> 249917.74 | D19: =SUM(D15:D18) -> 20082.26 | E19: =IF(B19=0,0,C19/B19) -> 0.92562126 | F19: =$B$11/12 -> 0.75 | G19: =IF(E19>F19*1.1,"Ahead of pace",IF(E19<F19*0.9,"Behind pace","On pace")) -> Ahead of pace | H19: =SUM(H15:H18) -> 27768.638 | I19: =IF($B$11>=12,0,D19/(12-$B$11)) -> 6694.0867
A20: Pacing rule: 'Ahead' = more than 10% above where a straight-line budget should be at this point in the year; 'Behind' = more than 10% below.
A22: 3. What's left for the rest of the year
A23: Scenario | B23: Total budget | C23: YTD spend | D23: Remaining | E23: Months left | F23: Budget left / month | G23: vs. avg monthly spend so far
A24: Current budget (Meta + Google + other) | B24: =B19 -> 270000 | C24: =$C$19 -> 249917.74 | D24: =B24-C24 -> 20082.26 | E24: =12-$B$11 -> 3 | F24: =IF(E24=0,0,D24/E24) -> 6694.0867 | G24: =IF($H$19=0,0,F24/$H$19-1) -> -0.75893356
A25: Stretch budget | B25: =$B$10 -> 350000 | C25: =$C$19 -> 249917.74 | D25: =B25-C25 -> 100082.26 | E25: =12-$B$11 -> 3 | F25: =IF(E25=0,0,D25/E25) -> 33360.753 | G25: =IF($H$19=0,0,F25/$H$19-1) -> 0.20138242
A26: Reading: a negative % in column G means you would need to spend LESS per month than you have on average so far to stay inside that budget.
A28: 4. Spend by quarter (from Monthly Spend tab) – last quarter = Q3 (Jul–Sep 2026)
A29: Platform | B29: Q1 (Jan–Mar) | C29: Q2 (Apr–Jun) | D29: Q3 (Jul–Sep) LAST QUARTER | E29: Q4 (Oct–Dec) | F29: Full year total | G29: Quarterly budget | H29: Q3 % of quarterly budget | I29: Q3 share of spend
A30: Meta | B30: =SUMIFS('Monthly Spend'!$C$6:$C$17,'Monthly Spend'!$B$6:$B$17,"Q1") -> 0 | C30: =SUMIFS('Monthly Spend'!$C$6:$C$17,'Monthly Spend'!$B$6:$B$17,"Q2") -> 0 | D30: =SUMIFS('Monthly Spend'!$C$6:$C$17,'Monthly Spend'!$B$6:$B$17,"Q3") -> 0 | E30: =SUMIFS('Monthly Spend'!$C$6:$C$17,'Monthly Spend'!$B$6:$B$17,"Q4") -> 0 | F30: =SUM(B30:E30) -> 0 | G30: =$B$6/4 -> 45000 | H30: =IF(G30=0,"n/a",D30/G30) -> 0 | I30: =IF($D$34=0,0,D30/$D$34) -> 0
A31: Google | B31: =SUMIFS('Monthly Spend'!$D$6:$D$17,'Monthly Spend'!$B$6:$B$17,"Q1") -> 0 | C31: =SUMIFS('Monthly Spend'!$D$6:$D$17,'Monthly Spend'!$B$6:$B$17,"Q2") -> 0 | D31: =SUMIFS('Monthly Spend'!$D$6:$D$17,'Monthly Spend'!$B$6:$B$17,"Q3") -> 0 | E31: =SUMIFS('Monthly Spend'!$D$6:$D$17,'Monthly Spend'!$B$6:$B$17,"Q4") -> 0 | F31: =SUM(B31:E31) -> 0 | G31: =$B$7/4 -> 22500 | H31: =IF(G31=0,"n/a",D31/G31) -> 0 | I31: =IF($D$34=0,0,D31/$D$34) -> 0
A32: LinkedIn | B32: =SUMIFS('Monthly Spend'!$E$6:$E$17,'Monthly Spend'!$B$6:$B$17,"Q1") -> 0 | C32: =SUMIFS('Monthly Spend'!$E$6:$E$17,'Monthly Spend'!$B$6:$B$17,"Q2") -> 0 | D32: =SUMIFS('Monthly Spend'!$E$6:$E$17,'Monthly Spend'!$B$6:$B$17,"Q3") -> 0 | E32: =SUMIFS('Monthly Spend'!$E$6:$E$17,'Monthly Spend'!$B$6:$B$17,"Q4") -> 0 | F32: =SUM(B32:E32) -> 0 | G32: =$B$8/4 -> 0 | H32: =IF(G32=0,"n/a",D32/G32) -> n/a | I32: =IF($D$34=0,0,D32/$D$34) -> 0
A33: ChatGPT | B33: =SUMIFS('Monthly Spend'!$F$6:$F$17,'Monthly Spend'!$B$6:$B$17,"Q1") -> 0 | C33: =SUMIFS('Monthly Spend'!$F$6:$F$17,'Monthly Spend'!$B$6:$B$17,"Q2") -> 0 | D33: =SUMIFS('Monthly Spend'!$F$6:$F$17,'Monthly Spend'!$B$6:$B$17,"Q3") -> 0 | E33: =SUMIFS('Monthly Spend'!$F$6:$F$17,'Monthly Spend'!$B$6:$B$17,"Q4") -> 0 | F33: =SUM(B33:E33) -> 0 | G33: =$B$9/4 -> 0 | H33: =IF(G33=0,"n/a",D33/G33) -> n/a | I33: =IF($D$34=0,0,D33/$D$34) -> 0
A34: TOTAL | B34: =SUM(B30:B33) -> 0 | C34: =SUM(C30:C33) -> 0 | D34: =SUM(D30:D33) -> 0 | E34: =SUM(E30:E33) -> 0 | F34: =SUM(B34:E34) -> 0 | G34: =SUM(G30:G33) -> 67500 | H34: =IF(G34=0,"n/a",D34/G34) -> 0 | I34: =IF($D$34=0,0,D34/$D$34) -> 0
A35: This section fills in automatically once monthly exports are pasted into the 'Monthly Spend' tab. Until then it shows '-'.
A37: 5. Territories at a glance (YTD, from territory report)
A38: Territory | B38: Total spend | C38: Territory budget | D38: % of budget | E38: Status
A39: ='By Territory'!A6 -> California | B39: ='By Territory'!D6 -> 28276.67 | C39: ='By Territory'!E6 -> 26630.37 | D39: ='By Territory'!F6 -> 1.0618204 | E39: ='By Territory'!H6 -> Over budget
A40: ='By Territory'!A7 -> New York | B40: ='By Territory'!D7 -> 14546.81 | C40: ='By Territory'!E7 -> 29658.15 | D40: ='By Territory'!F7 -> 0.49048272 | E40: ='By Territory'!H7 -> Under 60% used
A41: ='By Territory'!A8 -> New Jersey | B41: ='By Territory'!D8 -> 12020.55 | C41: ='By Territory'!E8 -> 22995.72 | D41: ='By Territory'!F8 -> 0.52272988 | E41: ='By Territory'!H8 -> Under 60% used
A42: ='By Territory'!A9 -> Washington DC | B42: ='By Territory'!D9 -> 8942.77 | C42: ='By Territory'!E9 -> 13663.52 | D42: ='By Territory'!F9 -> 0.65449972 | E42: ='By Territory'!H9 -> OK
A43: ='By Territory'!A10 -> Texas | B43: ='By Territory'!D10 -> 11513.35 | C43: ='By Territory'!E10 -> 22327.18 | D43: ='By Territory'!F10 -> 0.51566521 | E43: ='By Territory'!H10 -> Under 60% used
A44: ='By Territory'!A11 -> Florida | B44: ='By Territory'!D11 -> 11417.81 | C44: ='By Territory'!E11 -> 21992 | D44: ='By Territory'!F11 -> 0.51918016 | E44: ='By Territory'!H11 -> Under 60% used
A45: ='By Territory'!A12 -> Arizona | B45: ='By Territory'!D12 -> 6386.44 | C45: ='By Territory'!E12 -> 15328.36 | D45: ='By Territory'!F12 -> 0.41664209 | E45: ='By Territory'!H12 -> Under 60% used
...

Sheet Monthly Spend
A1: Monthly Spend 2026 (actuals)
A2: Paste one number per month per platform from the Meta / Google exports (USD). Everything else recalculates.
A3: Yellow cells are inputs. Leave a month blank until its data is closed – don't type 0 for a month you haven't checked.
A5: # | B5: Quarter | C5: Meta | D5: Google | E5: LinkedIn | F5: ChatGPT | G5: Total actual | H5: Monthly budget (1/12) | I5: Over / (under) budget | J5: Cumulative actual | K5: Cumulative budget | L5: Month
A6: 1 | B6: Q1 | G6: =IF(COUNT(C6:F6)=0,"",SUM(C6:F6)) | H6: =Overview!$B$19/12 -> 22500 | I6: =IF(G6="","",G6-H6) | J6: =IF(G6="","",SUM($G$6:G6)) | K6: =SUM($H$6:H6) -> 22500 | L6: Jan 2026
A7: 2 | B7: Q1 | G7: =IF(COUNT(C7:F7)=0,"",SUM(C7:F7)) | H7: =Overview!$B$19/12 -> 22500 | I7: =IF(G7="","",G7-H7) | J7: =IF(G7="","",SUM($G$6:G7)) | K7: =SUM($H$6:H7) -> 45000 | L7: Feb 2026
A8: 3 | B8: Q1 | G8: =IF(COUNT(C8:F8)=0,"",SUM(C8:F8)) | H8: =Overview!$B$19/12 -> 22500 | I8: =IF(G8="","",G8-H8) | J8: =IF(G8="","",SUM($G$6:G8)) | K8: =SUM($H$6:H8) -> 67500 | L8: Mar 2026
A9: 4 | B9: Q2 | G9: =IF(COUNT(C9:F9)=0,"",SUM(C9:F9)) | H9: =Overview!$B$19/12 -> 22500 | I9: =IF(G9="","",G9-H9) | J9: =IF(G9="","",SUM($G$6:G9)) | K9: =SUM($H$6:H9) -> 90000 | L9: Apr 2026
A10: 5 | B10: Q2 | G10: =IF(COUNT(C10:F10)=0,"",SUM(C10:F10)) | H10: =Overview!$B$19/12 -> 22500 | I10: =IF(G10="","",G10-H10) | J10: =IF(G10="","",SUM($G$6:G10)) | K10: =SUM($H$6:H10) -> 112500 | L10: May 2026
A11: 6 | B11: Q2 | G11: =IF(COUNT(C11:F11)=0,"",SUM(C11:F11)) | H11: =Overview!$B$19/12 -> 22500 | I11: =IF(G11="","",G11-H11) | J11: =IF(G11="","",SUM($G$6:G11)) | K11: =SUM($H$6:H11) -> 135000 | L11: Jun 2026
A12: 7 | B12: Q3 | G12: =IF(COUNT(C12:F12)=0,"",SUM(C12:F12)) | H12: =Overview!$B$19/12 -> 22500 | I12: =IF(G12="","",G12-H12) | J12: =IF(G12="","",SUM($G$6:G12)) | K12: =SUM($H$6:H12) -> 157500 | L12: Jul 2026
A13: 8 | B13: Q3 | G13: =IF(COUNT(C13:F13)=0,"",SUM(C13:F13)) | H13: =Overview!$B$19/12 -> 22500 | I13: =IF(G13="","",G13-H13) | J13: =IF(G13="","",SUM($G$6:G13)) | K13: =SUM($H$6:H13) -> 180000 | L13: Aug 2026
A14: 9 | B14: Q3 | G14: =IF(COUNT(C14:F14)=0,"",SUM(C14:F14)) | H14: =Overview!$B$19/12 -> 22500 | I14: =IF(G14="","",G14-H14) | J14: =IF(G14="","",SUM($G$6:G14)) | K14: =SUM($H$6:H14) -> 202500 | L14: Sep 2026
A15: 10 | B15: Q4 | G15: =IF(COUNT(C15:F15)=0,"",SUM(C15:F15)) | H15: =Overview!$B$19/12 -> 22500 | I15: =IF(G15="","",G15-H15) | J15: =IF(G15="","",SUM($G$6:G15)) | K15: =SUM($H$6:H15) -> 225000 | L15: Oct 2026
A16: 11 | B16: Q4 | G16: =IF(COUNT(C16:F16)=0,"",SUM(C16:F16)) | H16: =Overview!$B$19/12 -> 22500 | I16: =IF(G16="","",G16-H16) | J16: =IF(G16="","",SUM($G$6:G16)) | K16: =SUM($H$6:H16) -> 247500 | L16: Nov 2026
A17: 12 | B17: Q4 | G17: =IF(COUNT(C17:F17)=0,"",SUM(C17:F17)) | H17: =Overview!$B$19/12 -> 22500 | I17: =IF(G17="","",G17-H17) | J17: =IF(G17="","",SUM($G$6:G17)) | K17: =SUM($H$6:H17) -> 270000 | L17: Dec 2026
B18: TOTAL | C18: =SUM(C6:C17) -> 0 | D18: =SUM(D6:D17) -> 0 | E18: =SUM(E6:E17) -> 0 | F18: =SUM(F6:F17) -> 0 | G18: =SUM(G6:G17) -> 0 | H18: =SUM(H6:H17) -> 270000 | I18: =IF(COUNT(G6:G17)=0,"",SUMIF(G6:G17,"<>",I6:I17))

Sheet By Territory
A1: Spend by Territory – 2026 YTD
A2: Source: '2026_09_Spend_breakdown_per_location.xlsx' (shared by Felipe). Assumed to cover Jan–Sep 2026; please confirm.
A3: Blue numbers are copied from that file. Totals and % are recalculated here (they match the file's own totals). Replace with fresh numbers when you have them.
A5: Territory | B5: Meta | C5: Google | D5: Total spend | E5: Territory budget | F5: % of budget used | G5: Remaining | H5: Status | I5: Share of total spend | J5: Meta share of territory
A6: California | B6: 17825.83 | C6: 10450.84 | D6: =B6+C6 -> 28276.67 | E6: 26630.37 | F6: =IF(E6=0,0,D6/E6) -> 1.0618204 | G6: =E6-D6 -> -1646.3 | H6: =IF(F6>1,"Over budget",IF(F6<0.6,"Under 60% used","OK")) -> Over budget | I6: =IF($D$20=0,0,D6/$D$20) -> 0.11314391 | J6: =IF(D6=0,0,B6/D6) -> 0.63040768
A7: New York | B7: 8520.2 | C7: 6026.61 | D7: =B7+C7 -> 14546.81 | E7: 29658.15 | F7: =IF(E7=0,0,D7/E7) -> 0.49048272 | G7: =E7-D7 -> 15111.34 | H7: =IF(F7>1,"Over budget",IF(F7<0.6,"Under 60% used","OK")) -> Under 60% used | I7: =IF($D$20=0,0,D7/$D$20) -> 0.058206392 | J7: =IF(D7=0,0,B7/D7) -> 0.58570917
A8: New Jersey | B8: 8991.05 | C8: 3029.5 | D8: =B8+C8 -> 12020.55 | E8: 22995.72 | F8: =IF(E8=0,0,D8/E8) -> 0.52272988 | G8: =E8-D8 -> 10975.17 | H8: =IF(F8>1,"Over budget",IF(F8<0.6,"Under 60% used","OK")) -> Under 60% used | I8: =IF($D$20=0,0,D8/$D$20) -> 0.048098026 | J8: =IF(D8=0,0,B8/D8) -> 0.74797326
A9: Washington DC | B9: 7474.3 | C9: 1468.47 | D9: =B9+C9 -> 8942.77 | E9: 13663.52 | F9: =IF(E9=0,0,D9/E9) -> 0.65449972 | G9: =E9-D9 -> 4720.75 | H9: =IF(F9>1,"Over budget",IF(F9<0.6,"Under 60% used","OK")) -> OK | I9: =IF($D$20=0,0,D9/$D$20) -> 0.035782854 | J9: =IF(D9=0,0,B9/D9) -> 0.83579249
A10: Texas | B10: 5738.34 | C10: 5775.01 | D10: =B10+C10 -> 11513.35 | E10: 22327.18 | F10: =IF(E10=0,0,D10/E10) -> 0.51566521 | G10: =E10-D10 -> 10813.83 | H10: =IF(F10>1,"Over budget",IF(F10<0.6,"Under 60% used","OK")) -> Under 60% used | I10: =IF($D$20=0,0,D10/$D$20) -> 0.046068558 | J10: =IF(D10=0,0,B10/D10) -> 0.4984075
A11: Florida | B11: 5475.19 | C11: 5942.62 | D11: =B11+C11 -> 11417.81 | E11: 21992 | F11: =IF(E11=0,0,D11/E11) -> 0.51918016 | G11: =E11-D11 -> 10574.19 | H11: =IF(F11>1,"Over budget",IF(F11<0.6,"Under 60% used","OK")) -> Under 60% used | I11: =IF($D$20=0,0,D11/$D$20) -> 0.045686273 | J11: =IF(D11=0,0,B11/D11) -> 0.47953066
A12: Arizona | B12: 4435.23 | C12: 1951.21 | D12: =B12+C12 -> 6386.44 | E12: 15328.36 | F12: =IF(E12=0,0,D12/E12) -> 0.41664209 | G12: =E12-D12 -> 8941.92 | H12: =IF(F12>1,"Over budget",IF(F12<0.6,"Under 60% used","OK")) -> Under 60% used | I12: =IF($D$20=0,0,D12/$D$20) -> 0.025554168 | J12: =IF(D12=0,0,B12/D12) -> 0.69447611
A13: Indiana | B13: 4722.59 | C13: 1754.38 | D13: =B13+C13 -> 6476.97 | E13: 13663.52 | F13: =IF(E13=0,0,D13/E13) -> 0.47403378 | G13: =E13-D13 -> 7186.55 | H13: =IF(F13>1,"Over budget",IF(F13<0.6,"Under 60% used","OK")) -> Under 60% used | I13: =IF($D$20=0,0,D13/$D$20) -> 0.025916408 | J13: =IF(D13=0,0,B13/D13) -> 0.72913569
A14: Global Americas | B14: 29802.24 | C14: 17655.01 | D14: =B14+C14 -> 47457.25 | E14: 27967.45 | F14: =IF(E14=0,0,D14/E14) -> 1.6968744 | G14: =E14-D14 -> -19489.8 | H14: =IF(F14>1,"Over budget",IF(F14<0.6,"Under 60% used","OK")) -> Over budget | I14: =IF($D$20=0,0,D14/$D$20) -> 0.18989148 | J14: =IF(D14=0,0,B14/D14) -> 0.62798076
A15: UK | B15: 14033.47 | C15: 4412.69 | D15: =B15+C15 -> 18446.16 | E15: 22327.06 | F15: =IF(E15=0,0,D15/E15) -> 0.82617953 | G15: =E15-D15 -> 3880.9 | H15: =IF(F15>1,"Over budget",IF(F15<0.6,"Under 60% used","OK")) -> OK | I15: =IF($D$20=0,0,D15/$D$20) -> 0.073808926 | J15: =IF(D15=0,0,B15/D15) -> 0.76078002
A16: France | B16: 13603.69 | C16: 4415.75 | D16: =B16+C16 -> 18019.44 | E16: 22327.06 | F16: =IF(E16=0,0,D16/E16) -> 0.8070673 | G16: =E16-D16 -> 4307.62 | H16: =IF(F16>1,"Over budget",IF(F16<0.6,"Under 60% used","OK")) -> OK | I16: =IF($D$20=0,0,D16/$D$20) -> 0.072101484 | J16: =IF(D16=0,0,B16/D16) -> 0.75494521
A17: Italy | B17: 12132.84 | C17: 2356.54 | D17: =B17+C17 -> 14489.38 | E17: 18329.47 | F17: =IF(E17=0,0,D17/E17) -> 0.7904964 | G17: =E17-D17 -> 3840.09 | H17: =IF(F17>1,"Over budget",IF(F17<0.6,"Under 60% used","OK")) -> OK | I17: =IF($D$20=0,0,D17/$D$20) -> 0.057976597 | J17: =IF(D17=0,0,B17/D17) -> 0.83736088
... A19: Global EMEA | B19: 25413.03 | C19: 16094.63 | D19: =B19+C19 -> 41507.66 | E19: 27967.45 | F19: =IF(E19=0,0,D19/E19) -> 1.4841417 | G19: =E19-D19 -> -13540.21 | H19: =IF(F19>1,"Over budget",IF(F19<0.6,"Under 60% used","OK")) -> Over budget | I19: =IF($D$20=0,0,D19/$D$20) -> 0.16608529 | J19: =IF(D19=0,0,B19/D19) -> 0.61224916
A20: TOTAL | B20: =SUM(B6:B19) -> 167061.59 | C20: =SUM(C6:C19) -> 82856.15 | D20: =SUM(D6:D19) -> 249917.74 | E20: =SUM(E6:E19) -> 294676.29 | F20: =IF(E20=0,0,D20/E20) -> 0.84810943 | G20: =SUM(G6:G19) -> 44758.55 | H20: =IF(F20>1,"Over budget",IF(F20<0.6,"Under 60% used","OK")) -> OK | I20: =SUM(I6:I19) -> 1 | J20: =IF(D20=0,0,B20/D20) -> 0.66846631
A22: Regional roll-up
A23: Region | B23: Meta | C23: Google | D23: Total spend | E23: Territory budget | F23: % of budget used | G23: Share of total spend
A24: Americas (USCA) | B24: =SUM(B6:B14) -> 92984.97 | C24: =SUM(C6:C14) -> 54053.65 | D24: =SUM(D6:D14) -> 147038.62 | E24: =SUM(E6:E14) -> 194226.27 | F24: =IF(E24=0,0,D24/E24) -> 0.75704806 | G24: =IF($D$20=0,0,D24/$D$20) -> 0.58834807
A25: EMEA | B25: =SUM(B15:B19) -> 74076.62 | C25: =SUM(C15:C19) -> 28802.5 | D25: =SUM(D15:D19) -> 102879.12 | E25: =SUM(E15:E19) -> 100450.02 | F25: =IF(E25=0,0,D25/E25) -> 1.0241822 | G25: =IF($D$20=0,0,D25/$D$20) -> 0.41165193
A26: 2026 plan (Sep-2025 budget file) targeted ~50% USCA / 45% EMEA / 5% regional campaigns – compare with the shares above.
A28: Check: does the territory report match the monthly exports?
A29: Platform | B29: Territory report | C29: Monthly exports (Jan → last closed month) | D29: Difference | E29: Check
A30: Meta | B30: =B20 -> 167061.59 | C30: =SUMPRODUCT(('Monthly Spend'!$A$6:$A$17<=Overview!$B$11)*'Monthly Spend'!C$6:C$17) -> 0 | D30: =C30-B30 -> -167061.59 | E30: =IF(C30=0,"Monthly data not entered yet",IF(ABS(D30)<=B30*0.01,"Matches (±1%)","Gap – investigate")) -> Monthly data not entered yet
A31: Google | B31: =C20 -> 82856.15 | C31: =SUMPRODUCT(('Monthly Spend'!$A$6:$A$17<=Overview!$B$11)*'Monthly Spend'!D$6:D$17) -> 0 | D31: =C31-B31 -> -82856.15 | E31: =IF(C31=0,"Monthly data not entered yet",IF(ABS(D31)<=B31*0.01,"Matches (±1%)","Gap – investigate")) -> Monthly data not entered yet

Sheet Notes & Data Requests
A1: Notes, assumptions & data requests
A3: HOW TO USE
A4: 1 | B4: Paste monthly spend per platform into 'Monthly Spend' (yellow cells, USD).
A5: 2 | B5: Update 'Last month with closed data' on Overview (B11) – e.g. 10 once October closes.
A6: 3 | B6: Overview automatically switches its YTD figure from the territory report to your monthly exports once every closed month is filled in (see column J).
A7: 4 | B7: Check the reconciliation block at the bottom of 'By Territory' – the two sources should agree within ~1%.
A9: ASSUMPTIONS
A10: A1 | B10: Budget 2026: Meta $180k + Google $90k = $270k (as communicated to Felipe). Stretch $350k is a scenario, not approved.
A11: A2 | B11: Monthly / quarterly budget = annual ÷ 12 / ÷ 4 (straight-line). Change if Finance phases the budget differently.
A12: A3 | B12: 'Last quarter' = Q3 2026 (Jul–Sep), as of 8 Oct 2026.
A13: A4 | B13: The territory file '2026_09_Spend_breakdown_per_location' is assumed to be YTD Jan–Sep 2026 in USD.
A14: A5 | B14: The territory file's 'Budget' column totals $294,676, which does not match the $270k total. Its source needs confirming.
A15: A6 | B15: The original budget file '20250914_PNP_Paid_Budget' (last edited Sep 2025) planned $317.7k with a 25% LinkedIn share. That plan is out of date because LinkedIn isn't live, so this workbook uses the current $270k figures instead.
A17: DATA NEEDED FROM META
A18: M1 | B18: Ads Manager > Reports (or Campaigns tab) > select ALL ad accounts used by PNP.
A19: M2 | B19: Date range: 1 Jan 2026 – today. Breakdown > By Time > Month.
A20: M3 | B20: Columns: Account name, Account currency, Campaign name, Amount spent. Export as .xlsx or .csv.
A22: DATA NEEDED FROM GOOGLE ADS
A23: G1 | B23: From the Manager (MCC) account if there is one, otherwise each account separately.
A24: G2 | B24: Campaigns report, date range 1 Jan 2026 – today, Segment > Time > Month.
A25: G3 | B25: Columns: Account, Currency code, Campaign, Cost. Download as .xlsx or .csv.
A27: OPTIONAL
A28: O1 | B28: Same exports for 2025 (Jan–Dec) for a year-over-year comparison.
A29: O2 | B29: ChatGPT Ads spend by month, if it's already running.
A30: O3 | B30: Who produced the territory file, and how campaigns are mapped to territories (naming convention?).
