Workbook

Sheet Summary
A1: HubSpot Newsletter Audit – Summary data
A2: Source: HubSpot Analyze export and Health tab, pulled 8 Oct 2026.
A4: All marketing emails, 1 Oct 2025 – 30 Sep 2026 (vs previous 365 days)
A5: Metric | B5: Value | C5: Change vs previous 365 days
A6: Emails sent | B6: 1028641 | C6: -0.2193
A7: Unique emails | B7: 1032 | C7: –
A8: Delivered | B8: 1011458 | C8: –
A9: Delivery rate | B9: 0.9833 | C9: -0.0077
A10: Open rate | B10: 0.2688 | C10: -0.1138
A11: Click rate | B11: 0.0326 | C11: -0.0158
A12: Click-through rate (clicks ÷ opens) | B12: 0.1213 | C12: 0.1106
A13: Reply rate | B13: 0.0001 | C13: -0.2829
A14: Hard bounce rate | B14: 0.0129 | C14: 0.9746
A15: Unsubscribe rate | B15: 0.0081 | C15: 0.7244
A16: Spam report rate | B16: 0.0001 | C16: 0.7813
A19: Email health, last 30 days (5 Sep – 5 Oct 2026)
A20: Metric | B20: PnP | C20: HubSpot benchmark | D20: HubSpot rating
A21: Email health score | B21: 3 / 10 | C21: – | D21: Needs work
A22: Opens | B22: 0.25 | C22: 0.195 | D22: Very good
A23: Click-throughs | B23: 0.075 | C23: 0.085 | D23: Okay
A24: Hard bounces | B24: 0.0254 | C24: 0.0025 | D24: Poor
A25: Unsubscribes | B25: 0.0104 | C25: 0.0035 | D25: Poor
A26: Spam reports | B26: 5 | C26: – | D26: –
A27: Emails sent | B27: 158769 | C27: – | D27: –
A30: Email health by month (HubSpot Health tab)
A31: Month | B31: Health score (/10) | C31: Opens | D31: Click-throughs | E31: Hard bounces | F31: Unsubscribes | G31: Emails sent
A32: Oct 2025 | B32: 5 | C32: 0.299 | D32: 0.112 | E32: 0.0107 | F32: 0.0043 | G32: 112000
A33: Nov 2025 | B33: 6 | C33: 0.347 | D33: 0.147 | E33: 0.0056 | F33: 0.0042 | G33: 55700
A34: Dec 2025 | B34: 5 | C34: 0.279 | D34: 0.11 | E34: 0.0051 | F34: 0.0055 | G34: 56400
A35: Jan 2026 | B35: 5 | C35: 0.268 | D35: 0.142 | E35: 0.0128 | F35: 0.0047 | G35: 58600
A36: Feb 2026 | B36: 3 | C36: 0.292 | D36: 0.135 | E36: 0.0186 | F36: 0.007 | G36: 61100
A37: Mar 2026 | B37: 4 | C37: 0.285 | D37: 0.151 | E37: 0.0095 | F37: 0.0077 | G37: 72400
A38: Apr 2026 | B38: 3 | C38: 0.23 | D38: 0.128 | E38: 0.0129 | F38: 0.0066 | G38: 112200
A39: May 2026 | B39: 6 | C39: 0.297 | D39: 0.146 | E39: 0.0039 | F39: 0.0057 | G39: 77000
A40: Jun 2026 | B40: 4 | C40: 0.222 | D40: 0.124 | E40: 0.0076 | F40: 0.0055 | G40: 87700
A41: Jul 2026 | B41: 4 | C41: 0.225 | D41: 0.138 | E41: 0.0077 | F41: 0.0055 | G41: 70700
A42: Aug 2026 | B42: 3 | C42: 0.273 | D42: 0.091 | E42: 0.0177 | F42: 0.0116 | G42: 105200
A43: Sep 2026 | B43: 3 | C43: 0.267 | D43: 0.068 | E43: 0.0317 | F43: 0.0115 | G43: 124000
A44: Red = above HubSpot benchmark (hard bounces 0.25%, unsubscribes 0.35%).
A46: Device type (1 Oct 2025 – 30 Sep 2026)
...

Sheet Newsletters
A1: Recurring newsletters, 6 Aug – 30 Sep 2026
A2: Calculated from the 'Emails Aug-Sep' tab (duplicates excluded).
A4: Newsletter | B4: From name | C4: Subscription type | D4: Send dates | E4: Sends | F4: Avg. delivered | G4: Click rate | H4: Unsub rate | I4: Bounce rate
A5: Fintech & AI Fund Insights | B5: Brooke Ballinger | C5: Fintech & AI Fund Insights | D5: 09-23 | E5: =COUNTIFS('Emails Aug-Sep'!$E$5:$E$104,A5,'Emails Aug-Sep'!$N$5:$N$104,"No") -> 1 | F5: =IF(E5=0,0,SUMIFS('Emails Aug-Sep'!$F$5:$F$104,'Emails Aug-Sep'!$E$5:$E$104,A5,'Emails Aug-Sep'!$N$5:$N$104,"No")/E5) -> 8611 | G5: =IF(E5=0,0,SUMIFS('Emails Aug-Sep'!$I$5:$I$104,'Emails Aug-Sep'!$E$5:$E$104,A5,'Emails Aug-Sep'!$N$5:$N$104,"No")/SUMIFS('Emails Aug-Sep'!$F$5:$F$104,'Emails Aug-Sep'!$E$5:$E$104,A5,'Emails Aug-Sep'!$N$5:$N$104,"No")) -> 0.0069678318 | H5: =IF(E5=0,0,SUMIFS('Emails Aug-Sep'!$J$5:$J$104,'Emails Aug-Sep'!$E$5:$E$104,A5,'Emails Aug-Sep'!$N$5:$N$104,"No")/SUMIFS('Emails Aug-Sep'!$F$5:$F$104,'Emails Aug-Sep'!$E$5:$E$104,A5,'Emails Aug-Sep'!$N$5:$N$104,"No")) -> 0.014167925 | I5: =IF(E5=0,0,SUMIFS('Emails Aug-Sep'!$L$5:$L$104,'Emails Aug-Sep'!$E$5:$E$104,A5,'Emails Aug-Sep'!$N$5:$N$104,"No")/(SUMIFS('Emails Aug-Sep'!$F$5:$F$104,'Emails Aug-Sep'!$E$5:$E$104,A5,'Emails Aug-Sep'!$N$5:$N$104,"No")+SUMIFS('Emails Aug-Sep'!$L$5:$L$104,'Emails Aug-Sep'!$E$5:$E$104,A5,'Emails Aug-Sep'!$N$5:$N$104,"No"))) -> 0.012952774
A6: Italy Newsletter | B6: Tommaso Maschera | C6: Plug and Play Marketing Communications | D6: 08-06, 09-17 | E6: =COUNTIFS('Emails Aug-Sep'!$E$5:$E$104,A6,'Emails Aug-Sep'!$N$5:$N$104,"No") -> 2 | F6: =IF(E6=0,0,SUMIFS('Emails Aug-Sep'!$F$5:$F$104,'Emails Aug-Sep'!$E$5:$E$104,A6,'Emails Aug-Sep'!$N$5:$N$104,"No")/E6) -> 6624 | G6: =IF(E6=0,0,SUMIFS('Emails Aug-Sep'!$I$5:$I$104,'Emails Aug-Sep'!$E$5:$E$104,A6,'Emails Aug-Sep'!$N$5:$N$104,"No")/SUMIFS('Emails Aug-Sep'!$F$5:$F$104,'Emails Aug-Sep'!$E$5:$E$104,A6,'Emails Aug-Sep'!$N$5:$N$104,"No")) -> 0.012756643 | H6: =IF(E6=0,0,SUMIFS('Emails Aug-Sep'!$J$5:$J$104,'Emails Aug-Sep'!$E$5:$E$104,A6,'Emails Aug-Sep'!$N$5:$N$104,"No")/SUMIFS('Emails Aug-Sep'!$F$5:$F$104,'Emails Aug-Sep'!$E$5:$E$104,A6,'Emails Aug-Sep'!$N$5:$N$104,"No")) -> 0.0095863527 | I6: =IF(E6=0,0,SUMIFS('Emails Aug-Sep'!$L$5:$L$104,'Emails Aug-Sep'!$E$5:$E$104,A6,'Emails Aug-Sep'!$N$5:$N$104,"No")/(SUMIFS('Emails Aug-Sep'!$F$5:$F$104,'Emails Aug-Sep'!$E$5:$E$104,A6,'Emails Aug-Sep'!$N$5:$N$104,"No")+SUMIFS('Emails Aug-Sep'!$L$5:$L$104,'Emails Aug-Sep'!$E$5:$E$104,A6,'Emails Aug-Sep'!$N$5:$N$104,"No"))) -> 0.011490822
A7: UK Newsletter | B7: Kieran Borrett | C7: Plug and Play Marketing Communications | D7: 09-02, 09-30 | E7: =COUNTIFS('Emails Aug-Sep'!$E$5:$E$104,A7,'Emails Aug-Sep'!$N$5:$N$104,"No") -> 2 | F7: =IF(E7=0,0,SUMIFS('Emails Aug-Sep'!$F$5:$F$104,'Emails Aug-Sep'!$E$5:$E$104,A7,'Emails Aug-Sep'!$N$5:$N$104,"No")/E7) -> 6474.5 | G7: =IF(E7=0,0,SUMIFS('Emails Aug-Sep'!$I$5:$I$104,'Emails Aug-Sep'!$E$5:$E$104,A7,'Emails Aug-Sep'!$N$5:$N$104,"No")/SUMIFS('Emails Aug-Sep'!$F$5:$F$104,'Emails Aug-Sep'!$E$5:$E$104,A7,'Emails Aug-Sep'!$N$5:$N$104,"No")) -> 0.010502742 | H7: =IF(E7=0,0,SUMIFS('Emails Aug-Sep'!$J$5:$J$104,'Emails Aug-Sep'!$E$5:$E$104,A7,'Emails Aug-Sep'!$N$5:$N$104,"No")/SUMIFS('Emails Aug-Sep'!$F$5:$F$104,'Emails Aug-Sep'!$E$5:$E$104,A7,'Emails Aug-Sep'!$N$5:$N$104,"No")) -> 0.0098077072 | I7: =IF(E7=0,0,SUMIFS('Emails Aug-Sep'!$L$5:$L$104,'Emails Aug-Sep'!$E$5:$E$104,A7,'Emails Aug-Sep'!$N$5:$N$104,"No")/(SUMIFS('Emails Aug-Sep'!$F$5:$F$104,'Emails Aug-Sep'!$E$5:$E$104,A7,'Emails Aug-Sep'!$N$5:$N$104,"No")+SUMIFS('Emails Aug-Sep'!$L$5:$L$104,'Emails Aug-Sep'!$E$5:$E$104,A7,'Emails Aug-Sep'!$N$5:$N$104,"No"))) -> 0.0070546737
A8: Global Newsletter (GNL) | B8: Jacky from Plug and Play | C8: Plug and Play Global Newsletter | D8: 08-25, 08-25, 09-29 | E8: =COUNTIFS('Emails Aug-Sep'!$E$5:$E$104,A8,'Emails Aug-Sep'!$N$5:$N$104,"No") -> 3 | F8: =IF(E8=0,0,SUMIFS('Emails Aug-Sep'!$F$5:$F$104,'Emails Aug-Sep'!$E$5:$E$104,A8,'Emails Aug-Sep'!$N$5:$N$104,"No")/E8) -> 5748.3333 | G8: =IF(E8=0,0,SUMIFS('Emails Aug-Sep'!$I$5:$I$104,'Emails Aug-Sep'!$E$5:$E$104,A8,'Emails Aug-Sep'!$N$5:$N$104,"No")/SUMIFS('Emails Aug-Sep'!$F$5:$F$104,'Emails Aug-Sep'!$E$5:$E$104,A8,'Emails Aug-Sep'!$N$5:$N$104,"No")) -> 0.023543056 | H8: =IF(E8=0,0,SUMIFS('Emails Aug-Sep'!$J$5:$J$104,'Emails Aug-Sep'!$E$5:$E$104,A8,'Emails Aug-Sep'!$N$5:$N$104,"No")/SUMIFS('Emails Aug-Sep'!$F$5:$F$104,'Emails Aug-Sep'!$E$5:$E$104,A8,'Emails Aug-Sep'!$N$5:$N$104,"No")) -> 0.0053348797 | I8: =IF(E8=0,0,SUMIFS('Emails Aug-Sep'!$L$5:$L$104,'Emails Aug-Sep'!$E$5:$E$104,A8,'Emails Aug-Sep'!$N$5:$N$104,"No")/(SUMIFS('Emails Aug-Sep'!$F$5:$F$104,'Emails Aug-Sep'!$E$5:$E$104,A8,'Emails Aug-Sep'!$N$5:$N$104,"No")+SUMIFS('Emails Aug-Sep'!$L$5:$L$104,'Emails Aug-Sep'!$E$5:$E$104,A8,'Emails Aug-Sep'!$N$5:$N$104,"No"))) -> 0.0045026843
A9: Texas Newsletter | B9: Francis from Plug and Play | C9: Plug and Play Marketing Communications | D9: 08-26, 09-29 | E9: =COUNTIFS('Emails Aug-Sep'!$E$5:$E$104,A9,'Emails Aug-Sep'!$N$5:$N$104,"No") -> 2 | F9: =IF(E9=0,0,SUMIFS('Emails Aug-Sep'!$F$5:$F$104,'Emails Aug-Sep'!$E$5:$E$104,A9,'Emails Aug-Sep'!$N$5:$N$104,"No")/E9) -> 4746.5 | G9: =IF(E9=0,0,SUMIFS('Emails Aug-Sep'!$I$5:$I$104,'Emails Aug-Sep'!$E$5:$E$104,A9,'Emails Aug-Sep'!$N$5:$N$104,"No")/SUMIFS('Emails Aug-Sep'!$F$5:$F$104,'Emails Aug-Sep'!$E$5:$E$104,A9,'Emails Aug-Sep'!$N$5:$N$104,"No")) -> 0.028968714 | H9: =IF(E9=0,0,SUMIFS('Emails Aug-Sep'!$J$5:$J$104,'Emails Aug-Sep'!$E$5:$E$104,A9,'Emails Aug-Sep'!$N$5:$N$104,"No")/SUMIFS('Emails Aug-Sep'!$F$5:$F$104,'Emails Aug-Sep'!$E$5:$E$104,A9,'Emails Aug-Sep'!$N$5:$N$104,"No")) -> 0.0065311282 | I9: =IF(E9=0,0,SUMIFS('Emails Aug-Sep'!$L$5:$L$104,'Emails Aug-Sep'!$E$5:$E$104,A9,'Emails Aug-Sep'!$N$5:$N$104,"No")/(SUMIFS('Emails Aug-Sep'!$F$5:$F$104,'Emails Aug-Sep'!$E$5:$E$104,A9,'Emails Aug-Sep'!$N$5:$N$104,"No")+SUMIFS('Emails Aug-Sep'!$L$5:$L$104,'Emails Aug-Sep'!$E$5:$E$104,A9,'Emails Aug-Sep'!$N$5:$N$104,"No"))) -> 0.009391631
A10: Startup Autobahn Monthly | B10: STARTUP AUTOBAHN powered by Plug and Play | C10: Startup Autobahn Communications | D10: 09-07 | E10: =COUNTIFS('Emails Aug-Sep'!$E$5:$E$104,A10,'Emails Aug-Sep'!$N$5:$N$104,"No") -> 1 | F10: =IF(E10=0,0,SUMIFS('Emails Aug-Sep'!$F$5:$F$104,'Emails Aug-Sep'!$E$5:$E$104,A10,'Emails Aug-Sep'!$N$5:$N$104,"No")/E10) -> 4384 | G10: =IF(E10=0,0,SUMIFS('Emails Aug-Sep'!$I$5:$I$104,'Emails Aug-Sep'!$E$5:$E$104,A10,'Emails Aug-Sep'!$N$5:$N$104,"No")/SUMIFS('Emails Aug-Sep'!$F$5:$F$104,'Emails Aug-Sep'!$E$5:$E$104,A10,'Emails Aug-Sep'!$N$5:$N$104,"No")) -> 0.020985401 | H10: =IF(E10=0,0,SUMIFS('Emails Aug-Sep'!$J$5:$J$104,'Emails Aug-Sep'!$E$5:$E$104,A10,'Emails Aug-Sep'!$N$5:$N$104,"No")/SUMIFS('Emails Aug-Sep'!$F$5:$F$104,'Emails Aug-Sep'!$E$5:$E$104,A10,'Emails Aug-Sep'!$N$5:$N$104,"No")) -> 0.0034215328 | I10: =IF(E10=0,0,SUMIFS('Emails Aug-Sep'!$L$5:$L$104,'Emails Aug-Sep'!$E$5:$E$104,A10,'Emails Aug-Sep'!$N$5:$N$104,"No")/(SUMIFS('Emails Aug-Sep'!$F$5:$F$104,'Emails Aug-Sep'!$E$5:$E$104,A10,'Emails Aug-Sep'!$N$5:$N$104,"No")+SUMIFS('Emails Aug-Sep'!$L$5:$L$104,'Emails Aug-Sep'!$E$5:$E$104,A10,'Emails Aug-Sep'!$N$5:$N$104,"No"))) -> 0.010160307
A11: Central Asia & Caucasus Latest News | B11: Sofi from Plug and Play Central Asia and Caucasus | C11: Plug and Play Marketing Communications | D11: 09-04 | E11: =COUNTIFS('Emails Aug-Sep'!$E$5:$E$104,A11,'Emails Aug-Sep'!$N$5:$N$104,"No") -> 1 | F11: =IF(E11=0,0,SUMIFS('Emails Aug-Sep'!$F$5:$F$104,'Emails Aug-Sep'!$E$5:$E$104,A11,'Emails Aug-Sep'!$N$5:$N$104,"No")/E11) -> 3302 | G11: =IF(E11=0,0,SUMIFS('Emails Aug-Sep'!$I$5:$I$104,'Emails Aug-Sep'!$E$5:$E$104,A11,'Emails Aug-Sep'!$N$5:$N$104,"No")/SUMIFS('Emails Aug-Sep'!$F$5:$F$104,'Emails Aug-Sep'!$E$5:$E$104,A11,'Emails Aug-Sep'!$N$5:$N$104,"No")) -> 0.015142338 | H11: =IF(E11=0,0,SUMIFS('Emails Aug-Sep'!$J$5:$J$104,'Emails Aug-Sep'!$E$5:$E$104,A11,'Emails Aug-Sep'!$N$5:$N$104,"No")/SUMIFS('Emails Aug-Sep'!$F$5:$F$104,'Emails Aug-Sep'!$E$5:$E$104,A11,'Emails Aug-Sep'!$N$5:$N$104,"No")) -> 0.007571169 | I11: =IF(E11=0,0,SUMIFS('Emails Aug-Sep'!$L$5:$L$104,'Emails Aug-Sep'!$E$5:$E$104,A11,'Emails Aug-Sep'!$N$5:$N$104,"No")/(SUMIFS('Emails Aug-Sep'!$F$5:$F$104,'Emails Aug-Sep'!$E$5:$E$104,A11,'Emails Aug-Sep'!$N$5:$N$104,"No")+SUMIFS('Emails Aug-Sep'!$L$5:$L$104,'Emails Aug-Sep'!$E$5:$E$104,A11,'Emails Aug-Sep'!$N$5:$N$104,"No"))) -> 0.022209061
A12: APAC Newsletter | B12: Plug and Play APAC | C12: Plug and Play APAC | D12: 08-19, 09-23 | E12: =COUNTIFS('Emails Aug-Sep'!$E$5:$E$104,A12,'Emails Aug-Sep'!$N$5:$N$104,"No") -> 2 | F12: =IF(E12=0,0,SUMIFS('Emails Aug-Sep'!$F$5:$F$104,'Emails Aug-Sep'!$E$5:$E$104,A12,'Emails Aug-Sep'!$N$5:$N$104,"No")/E12) -> 2756 | G12: =IF(E12=0,0,SUMIFS('Emails Aug-Sep'!$I$5:$I$104,'Emails Aug-Sep'!$E$5:$E$104,A12,'Emails Aug-Sep'!$N$5:$N$104,"No")/SUMIFS('Emails Aug-Sep'!$F$5:$F$104,'Emails Aug-Sep'!$E$5:$E$104,A12,'Emails Aug-Sep'!$N$5:$N$104,"No")) -> 0.029571843 | H12: =IF(E12=0,0,SUMIFS('Emails Aug-Sep'!$J$5:$J$104,'Emails Aug-Sep'!$E$5:$E$104,A12,'Emails Aug-Sep'!$N$5:$N$104,"No")/SUMIFS('Emails Aug-Sep'!$F$5:$F$104,'Emails Aug-Sep'!$E$5:$E$104,A12,'Emails Aug-Sep'!$N$5:$N$104,"No")) -> 0.003628447 | I12: =IF(E12=0,0,SUMIFS('Emails Aug-Sep'!$L$5:$L$104,'Emails Aug-Sep'!$E$5:$E$104,A12,'Emails Aug-Sep'!$N$5:$N$104,"No")/(SUMIFS('Emails Aug-Sep'!$F$5:$F$104,'Emails Aug-Sep'!$E$5:$E$104,A12,'Emails Aug-Sep'!$N$5:$N$104,"No")+SUMIFS('Emails Aug-Sep'!$L$5:$L$104,'Emails Aug-Sep'!$E$5:$E$104,A12,'Emails Aug-Sep'!$N$5:$N$104,"No"))) -> 0.006309717
A13: Seattle Community Newsletter | B13: Emmanuel Chan | C13: Plug and Play Marketing Communications | D13: 09-01 | E13: =COUNTIFS('Emails Aug-Sep'!$E$5:$E$104,A13,'Emails Aug-Sep'!$N$5:$N$104,"No") -> 1 | F13: =IF(E13=0,0,SUMIFS('Emails Aug-Sep'!$F$5:$F$104,'Emails Aug-Sep'!$E$5:$E$104,A13,'Emails Aug-Sep'!$N$5:$N$104,"No")/E13) -> 1787 | G13: =IF(E13=0,0,SUMIFS('Emails Aug-Sep'!$I$5:$I$104,'Emails Aug-Sep'!$E$5:$E$104,A13,'Emails Aug-Sep'!$N$5:$N$104,"No")/SUMIFS('Emails Aug-Sep'!$F$5:$F$104,'Emails Aug-Sep'!$E$5:$E$104,A13,'Emails Aug-Sep'!$N$5:$N$104,"No")) -> 0.021824287 | H13: =IF(E13=0,0,SUMIFS('Emails Aug-Sep'!$J$5:$J$104,'Emails Aug-Sep'!$E$5:$E$104,A13,'Emails Aug-Sep'!$N$5:$N$104,"No")/SUMIFS('Emails Aug-Sep'!$F$5:$F$104,'Emails Aug-Sep'!$E$5:$E$104,A13,'Emails Aug-Sep'!$N$5:$N$104,"No")) -> 0.0055959709 | I13: =IF(E13=0,0,SUMIFS('Emails Aug-Sep'!$L$5:$L$104,'Emails Aug-Sep'!$E$5:$E$104,A13,'Emails Aug-Sep'!$N$5:$N$104,"No")/(SUMIFS('Emails Aug-Sep'!$F$5:$F$104,'Emails Aug-Sep'!$E$5:$E$104,A13,'Emails Aug-Sep'!$N$5:$N$104,"No")+SUMIFS('Emails Aug-Sep'!$L$5:$L$104,'Emails Aug-Sep'!$E$5:$E$104,A13,'Emails Aug-Sep'!$N$5:$N$104,"No"))) -> 0.0072222222
A14: Indiana Medtech + Lifetech Newsletter | B14: Plug and Play Indiana | C14: Plug and Play Marketing Communications | D14: 09-18 | E14: =COUNTIFS('Emails Aug-Sep'!$E$5:$E$104,A14,'Emails Aug-Sep'!$N$5:$N$104,"No") -> 1 | F14: =IF(E14=0,0,SUMIFS('Emails Aug-Sep'!$F$5:$F$104,'Emails Aug-Sep'!$E$5:$E$104,A14,'Emails Aug-Sep'!$N$5:$N$104,"No")/E14) -> 1430 | G14: =IF(E14=0,0,SUMIFS('Emails Aug-Sep'!$I$5:$I$104,'Emails Aug-Sep'!$E$5:$E$104,A14,'Emails Aug-Sep'!$N$5:$N$104,"No")/SUMIFS('Emails Aug-Sep'!$F$5:$F$104,'Emails Aug-Sep'!$E$5:$E$104,A14,'Emails Aug-Sep'!$N$5:$N$104,"No")) -> 0.013286713 | H14: =IF(E14=0,0,SUMIFS('Emails Aug-Sep'!$J$5:$J$104,'Emails Aug-Sep'!$E$5:$E$104,A14,'Emails Aug-Sep'!$N$5:$N$104,"No")/SUMIFS('Emails Aug-Sep'!$F$5:$F$104,'Emails Aug-Sep'!$E$5:$E$104,A14,'Emails Aug-Sep'!$N$5:$N$104,"No")) -> 0.0055944056 | I14: =IF(E14=0,0,SUMIFS('Emails Aug-Sep'!$L$5:$L$104,'Emails Aug-Sep'!$E$5:$E$104,A14,'Emails Aug-Sep'!$N$5:$N$104,"No")/(SUMIFS('Emails Aug-Sep'!$F$5:$F$104,'Emails Aug-Sep'!$E$5:$E$104,A14,'Emails Aug-Sep'!$N$5:$N$104,"No")+SUMIFS('Emails Aug-Sep'!$L$5:$L$104,'Emails Aug-Sep'!$E$5:$E$104,A14,'Emails Aug-Sep'!$N$5:$N$104,"No"))) -> 0.0069444444
A15: Türkiye Newsletter | B15: Zeynep from Plug and Play | C15: Plug and Play Marketing Communications | D15: 08-31 | E15: =COUNTIFS('Emails Aug-Sep'!$E$5:$E$104,A15,'Emails Aug-Sep'!$N$5:$N$104,"No") -> 1 | F15: =IF(E15=0,0,SUMIFS('Emails Aug-Sep'!$F$5:$F$104,'Emails Aug-Sep'!$E$5:$E$104,A15,'Emails Aug-Sep'!$N$5:$N$104,"No")/E15) -> 1420 | G15: =IF(E15=0,0,SUMIFS('Emails Aug-Sep'!$I$5:$I$104,'Emails Aug-Sep'!$E$5:$E$104,A15,'Emails Aug-Sep'!$N$5:$N$104,"No")/SUMIFS('Emails Aug-Sep'!$F$5:$F$104,'Emails Aug-Sep'!$E$5:$E$104,A15,'Emails Aug-Sep'!$N$5:$N$104,"No")) -> 0.019014085 | H15: =IF(E15=0,0,SUMIFS('Emails Aug-Sep'!$J$5:$J$104,'Emails Aug-Sep'!$E$5:$E$104,A15,'Emails Aug-Sep'!$N$5:$N$104,"No")/SUMIFS('Emails Aug-Sep'!$F$5:$F$104,'Emails Aug-Sep'!$E$5:$E$104,A15,'Emails Aug-Sep'!$N$5:$N$104,"No")) -> 0.0056338028 | I15: =IF(E15=0,0,SUMIFS('Emails Aug-Sep'!$L$5:$L$104,'Emails Aug-Sep'!$E$5:$E$104,A15,'Emails Aug-Sep'!$N$5:$N$104,"No")/(SUMIFS('Emails Aug-Sep'!$F$5:$F$104,'Emails Aug-Sep'!$E$5:$E$104,A15,'Emails Aug-Sep'!$N$5:$N$104,"No")+SUMIFS('Emails Aug-Sep'!$L$5:$L$104,'Emails Aug-Sep'!$E$5:$E$104,A15,'Emails Aug-Sep'!$N$5:$N$104,"No"))) -> 0.0076869322
A16: Japan Newsletter | B16: Plug and Play Japan | C16: Plug and Play Japan | D16: 08-19, 09-02, 09-16, 09-30 | E16: =COUNTIFS('Emails Aug-Sep'!$E$5:$E$104,A16,'Emails Aug-Sep'!$N$5:$N$104,"No") -> 4 | F16: =IF(E16=0,0,SUMIFS('Emails Aug-Sep'!$F$5:$F$104,'Emails Aug-Sep'!$E$5:$E$104,A16,'Emails Aug-Sep'!$N$5:$N$104,"No")/E16) -> 988.75 | G16: =IF(E16=0,0,SUMIFS('Emails Aug-Sep'!$I$5:$I$104,'Emails Aug-Sep'!$E$5:$E$104,A16,'Emails Aug-Sep'!$N$5:$N$104,"No")/SUMIFS('Emails Aug-Sep'!$F$5:$F$104,'Emails Aug-Sep'!$E$5:$E$104,A16,'Emails Aug-Sep'!$N$5:$N$104,"No")) -> 0.096333755 | H16: =IF(E16=0,0,SUMIFS('Emails Aug-Sep'!$J$5:$J$104,'Emails Aug-Sep'!$E$5:$E$104,A16,'Emails Aug-Sep'!$N$5:$N$104,"No")/SUMIFS('Emails Aug-Sep'!$F$5:$F$104,'Emails Aug-Sep'!$E$5:$E$104,A16,'Emails Aug-Sep'!$N$5:$N$104,"No")) -> 0.000505689 | I16: =IF(E16=0,0,SUMIFS('Emails Aug-Sep'!$L$5:$L$104,'Emails Aug-Sep'!$E$5:$E$104,A16,'Emails Aug-Sep'!$N$5:$N$104,"No")/(SUMIFS('Emails Aug-Sep'!$F$5:$F$104,'Emails Aug-Sep'!$E$5:$E$104,A16,'Emails Aug-Sep'!$N$5:$N$104,"No")+SUMIFS('Emails Aug-Sep'!$L$5:$L$104,'Emails Aug-Sep'!$E$5:$E$104,A16,'Emails Aug-Sep'!$N$5:$N$104,"No"))) -> 0.0020186727
... A26: Shamrock Foods Monthly Signal | B26: Plug and Play Supply Chain | C26: Plug and Play Marketing Communications | D26: 09-14 | E26: =COUNTIFS('Emails Aug-Sep'!$E$5:$E$104,A26,'Emails Aug-Sep'!$N$5:$N$104,"No") -> 1 | F26: =IF(E26=0,0,SUMIFS('Emails Aug-Sep'!$F$5:$F$104,'Emails Aug-Sep'!$E$5:$E$104,A26,'Emails Aug-Sep'!$N$5:$N$104,"No")/E26) -> 7 | G26: =IF(E26=0,0,SUMIFS('Emails Aug-Sep'!$I$5:$I$104,'Emails Aug-Sep'!$E$5:$E$104,A26,'Emails Aug-Sep'!$N$5:$N$104,"No")/SUMIFS('Emails Aug-Sep'!$F$5:$F$104,'Emails Aug-Sep'!$E$5:$E$104,A26,'Emails Aug-Sep'!$N$5:$N$104,"No")) -> 0 | H26: =IF(E26=0,0,SUMIFS('Emails Aug-Sep'!$J$5:$J$104,'Emails Aug-Sep'!$E$5:$E$104,A26,'Emails Aug-Sep'!$N$5:$N$104,"No")/SUMIFS('Emails Aug-Sep'!$F$5:$F$104,'Emails Aug-Sep'!$E$5:$E$104,A26,'Emails Aug-Sep'!$N$5:$N$104,"No")) -> 0 | I26: =IF(E26=0,0,SUMIFS('Emails Aug-Sep'!$L$5:$L$104,'Emails Aug-Sep'!$E$5:$E$104,A26,'Emails Aug-Sep'!$N$5:$N$104,"No")/(SUMIFS('Emails Aug-Sep'!$F$5:$F$104,'Emails Aug-Sep'!$E$5:$E$104,A26,'Emails Aug-Sep'!$N$5:$N$104,"No")+SUMIFS('Emails Aug-Sep'!$L$5:$L$104,'Emails Aug-Sep'!$E$5:$E$104,A26,'Emails Aug-Sep'!$N$5:$N$104,"No"))) -> 0
A27: Red = unsubscribe rate above HubSpot benchmark (0.35%). Send dates are MM-DD, 2026.
A29: All emails by number of recipients, 6 Aug – 30 Sep 2026
A30: Delivered per email | B30: Emails | C30: Delivered | D30: Click rate | E30: Unsub rate | F30: Bounce rate
A31: Fewer than 300 | B31: =COUNTIFS('Emails Aug-Sep'!$F$5:$F$104,">=0",'Emails Aug-Sep'!$F$5:$F$104,"<300",'Emails Aug-Sep'!$N$5:$N$104,"No") -> 47 | C31: =SUMIFS('Emails Aug-Sep'!$F$5:$F$104,'Emails Aug-Sep'!$F$5:$F$104,">=0",'Emails Aug-Sep'!$F$5:$F$104,"<300",'Emails Aug-Sep'!$N$5:$N$104,"No") -> 4300 | D31: =IF(C31=0,0,SUMIFS('Emails Aug-Sep'!$I$5:$I$104,'Emails Aug-Sep'!$F$5:$F$104,">=0",'Emails Aug-Sep'!$F$5:$F$104,"<300",'Emails Aug-Sep'!$N$5:$N$104,"No")/C31) -> 0.11930233 | E31: =IF(C31=0,0,SUMIFS('Emails Aug-Sep'!$J$5:$J$104,'Emails Aug-Sep'!$F$5:$F$104,">=0",'Emails Aug-Sep'!$F$5:$F$104,"<300",'Emails Aug-Sep'!$N$5:$N$104,"No")/C31) -> 0.0018604651 | F31: =IF(C31=0,0,SUMIFS('Emails Aug-Sep'!$L$5:$L$104,'Emails Aug-Sep'!$F$5:$F$104,">=0",'Emails Aug-Sep'!$F$5:$F$104,"<300",'Emails Aug-Sep'!$N$5:$N$104,"No")/(C31+SUMIFS('Emails Aug-Sep'!$L$5:$L$104,'Emails Aug-Sep'!$F$5:$F$104,">=0",'Emails Aug-Sep'!$F$5:$F$104,"<300",'Emails Aug-Sep'!$N$5:$N$104,"No"))) -> 0.0023201856
A32: 300 – 4,999 | B32: =COUNTIFS('Emails Aug-Sep'!$F$5:$F$104,">=300",'Emails Aug-Sep'!$F$5:$F$104,"<5000",'Emails Aug-Sep'!$N$5:$N$104,"No") -> 39 | C32: =SUMIFS('Emails Aug-Sep'!$F$5:$F$104,'Emails Aug-Sep'!$F$5:$F$104,">=300",'Emails Aug-Sep'!$F$5:$F$104,"<5000",'Emails Aug-Sep'!$N$5:$N$104,"No") -> 78299 | D32: =IF(C32=0,0,SUMIFS('Emails Aug-Sep'!$I$5:$I$104,'Emails Aug-Sep'!$F$5:$F$104,">=300",'Emails Aug-Sep'!$F$5:$F$104,"<5000",'Emails Aug-Sep'!$N$5:$N$104,"No")/C32) -> 0.025811313 | E32: =IF(C32=0,0,SUMIFS('Emails Aug-Sep'!$J$5:$J$104,'Emails Aug-Sep'!$F$5:$F$104,">=300",'Emails Aug-Sep'!$F$5:$F$104,"<5000",'Emails Aug-Sep'!$N$5:$N$104,"No")/C32) -> 0.0081737953 | F32: =IF(C32=0,0,SUMIFS('Emails Aug-Sep'!$L$5:$L$104,'Emails Aug-Sep'!$F$5:$F$104,">=300",'Emails Aug-Sep'!$F$5:$F$104,"<5000",'Emails Aug-Sep'!$N$5:$N$104,"No")/(C32+SUMIFS('Emails Aug-Sep'!$L$5:$L$104,'Emails Aug-Sep'!$F$5:$F$104,">=300",'Emails Aug-Sep'!$F$5:$F$104,"<5000",'Emails Aug-Sep'!$N$5:$N$104,"No"))) -> 0.011513552
A33: 5,000 or more | B33: =COUNTIFS('Emails Aug-Sep'!$F$5:$F$104,">=5000",'Emails Aug-Sep'!$F$5:$F$104,"<1000000000",'Emails Aug-Sep'!$N$5:$N$104,"No") -> 11 | C33: =SUMIFS('Emails Aug-Sep'!$F$5:$F$104,'Emails Aug-Sep'!$F$5:$F$104,">=5000",'Emails Aug-Sep'!$F$5:$F$104,"<1000000000",'Emails Aug-Sep'!$N$5:$N$104,"No") -> 131465 | D33: =IF(C33=0,0,SUMIFS('Emails Aug-Sep'!$I$5:$I$104,'Emails Aug-Sep'!$F$5:$F$104,">=5000",'Emails Aug-Sep'!$F$5:$F$104,"<1000000000",'Emails Aug-Sep'!$N$5:$N$104,"No")/C33) -> 0.014247138 | E33: =IF(C33=0,0,SUMIFS('Emails Aug-Sep'!$J$5:$J$104,'Emails Aug-Sep'!$F$5:$F$104,">=5000",'Emails Aug-Sep'!$F$5:$F$104,"<1000000000",'Emails Aug-Sep'!$N$5:$N$104,"No")/C33) -> 0.015593504 | F33: =IF(C33=0,0,SUMIFS('Emails Aug-Sep'!$L$5:$L$104,'Emails Aug-Sep'!$F$5:$F$104,">=5000",'Emails Aug-Sep'!$F$5:$F$104,"<1000000000",'Emails Aug-Sep'!$N$5:$N$104,"No")/(C33+SUMIFS('Emails Aug-Sep'!$L$5:$L$104,'Emails Aug-Sep'!$F$5:$F$104,">=5000",'Emails Aug-Sep'!$F$5:$F$104,"<1000000000",'Emails Aug-Sep'!$N$5:$N$104,"No"))) -> 0.041821243
A34: Total | B34: =SUM(B31:B33) -> 97 | C34: =SUM(C31:C33) -> 214064
A37: 3 emails with the most bounces, 6 Aug – 30 Sep 2026
A38: Email | B38: Send date | C38: Delivered | D38: Unsubscribes | E38: Bounces | F38: Share of all unsubscribes | G38: Share of all bounces
A39: JTP | JAP_Sansan List_Consent Mail_20260909 | B39: 2026-09-18 | C39: =SUMIFS('Emails Aug-Sep'!$F$5:$F$104,'Emails Aug-Sep'!$A$5:$A$104,A39,'Emails Aug-Sep'!$N$5:$N$104,"No") -> 38385 | D39: =SUMIFS('Emails Aug-Sep'!$J$5:$J$104,'Emails Aug-Sep'!$A$5:$A$104,A39,'Emails Aug-Sep'!$N$5:$N$104,"No") -> 735 | E39: =SUMIFS('Emails Aug-Sep'!$L$5:$L$104,'Emails Aug-Sep'!$A$5:$A$104,A39,'Emails Aug-Sep'!$N$5:$N$104,"No") -> 3576 | F39: =D39/SUMIFS('Emails Aug-Sep'!$J$5:$J$104,'Emails Aug-Sep'!$N$5:$N$104,"No") -> 0.27242402 | G39: =E39/SUMIFS('Emails Aug-Sep'!$L$5:$L$104,'Emails Aug-Sep'!$N$5:$N$104,"No") -> 0.53693694
A40: Plug and Play's 2026 Corporate Partnership Survey - Third Batch | B40: 2026-08-25 | C40: =SUMIFS('Emails Aug-Sep'!$F$5:$F$104,'Emails Aug-Sep'!$A$5:$A$104,A40,'Emails Aug-Sep'!$N$5:$N$104,"No") -> 13111 | D40: =SUMIFS('Emails Aug-Sep'!$J$5:$J$104,'Emails Aug-Sep'!$A$5:$A$104,A40,'Emails Aug-Sep'!$N$5:$N$104,"No") -> 252 | E40: =SUMIFS('Emails Aug-Sep'!$L$5:$L$104,'Emails Aug-Sep'!$A$5:$A$104,A40,'Emails Aug-Sep'!$N$5:$N$104,"No") -> 826 | F40: =D40/SUMIFS('Emails Aug-Sep'!$J$5:$J$104,'Emails Aug-Sep'!$N$5:$N$104,"No") -> 0.09340252 | G40: =E40/SUMIFS('Emails Aug-Sep'!$L$5:$L$104,'Emails Aug-Sep'!$N$5:$N$104,"No") -> 0.12402402
A41: FR_ALIBABA COCREATE STARUP EMAIL FINAL | B41: 2026-08-17 | C41: =SUMIFS('Emails Aug-Sep'!$F$5:$F$104,'Emails Aug-Sep'!$A$5:$A$104,A41,'Emails Aug-Sep'!$N$5:$N$104,"No") -> 18358 | D41: =SUMIFS('Emails Aug-Sep'!$J$5:$J$104,'Emails Aug-Sep'!$A$5:$A$104,A41,'Emails Aug-Sep'!$N$5:$N$104,"No") -> 417 | E41: =SUMIFS('Emails Aug-Sep'!$L$5:$L$104,'Emails Aug-Sep'!$A$5:$A$104,A41,'Emails Aug-Sep'!$N$5:$N$104,"No") -> 834 | F41: =D41/SUMIFS('Emails Aug-Sep'!$J$5:$J$104,'Emails Aug-Sep'!$N$5:$N$104,"No") -> 0.15455893 | G41: =E41/SUMIFS('Emails Aug-Sep'!$L$5:$L$104,'Emails Aug-Sep'!$N$5:$N$104,"No") -> 0.12522523
A42: These 3 emails combined | C42: =SUM(C39:C41) -> 69854 | D42: =SUM(D39:D41) -> 1404 | E42: =SUM(E39:E41) -> 5236 | F42: =D42/SUMIFS('Emails Aug-Sep'!$J$5:$J$104,'Emails Aug-Sep'!$N$5:$N$104,"No") -> 0.52038547 | G42: =E42/SUMIFS('Emails Aug-Sep'!$L$5:$L$104,'Emails Aug-Sep'!$N$5:$N$104,"No") -> 0.78618619

Sheet Locations
A1: Location newsletters and subscription types
A2: Sources: Emails Aug-Sep tab; Settings › Marketing › Email › Subscriptions; HubSpot teams list (8 Oct 2026).
A4: Location | B4: Newsletter | C4: Subscription type used | D4: Location's own subscription type | E4: Status of own type | F4: HubSpot team (users)
A5: UK | B5: UK Newsletter | C5: Plug and Play Marketing Communications | D5: Plug and Play UK Communications | E5: Archived | F5: London (3)
A6: Italy | B6: Italy Newsletter | C6: Plug and Play Marketing Communications | D6: Plug and Play Italy (2 types) | E6: Archived | F6: Italy (3), ITALY BD (2)
A7: Texas | B7: Texas Newsletter | C7: Plug and Play Marketing Communications | D7: Plug and Play Texas | E7: Archived | F7: –
A8: Seattle | B8: Seattle Community Newsletter | C8: Plug and Play Marketing Communications | D8: Plug and Play Seattle | E8: Archived | F8: –
A9: Indiana | B9: Indiana Medtech + Lifetech Newsletter | C9: Plug and Play Marketing Communications | D9: Plug and Play Indiana | E9: Archived | F9: –
A10: Türkiye | B10: Türkiye Newsletter | C10: Plug and Play Marketing Communications | D10: Plug and Play Istanbul Communications | E10: Archived | F10: Istanbul (1)
A11: Central Asia & Caucasus | B11: Central Asia & Caucasus Latest News | C11: Plug and Play Marketing Communications | D11: Plug and Play Central Asia & Caucasus | E11: Archived | F11: Kazakhstan (1)
A12: Cyprus | B12: Cyprus Latest News | C12: Plug and Play Marketing Communications | D12: None | E12: – | F12: –
A13: Japan | B13: Japan Newsletter | C13: Plug and Play Japan | D13: Plug and Play Japan | E13: Active | F13: Japan (32)
A14: APAC | B14: APAC Newsletter | C14: Plug and Play APAC | D14: Plug and Play APAC | E14: Active | F14: APAC (5)
A16: =COUNTIF(C5:C14,"Plug and Play Marketing Communications")&" of 10 location newsletters use 'Plug and Play Marketing Communications'." -> 8 of 10 location newsletters use 'Plug and Play Marketing Communications'.
A17: =COUNTIFS('Emails Aug-Sep'!$D$5:$D$104,"Plug and Play Marketing Communications",'Emails Aug-Sep'!$N$5:$N$104,"No")&" of "&COUNTIFS('Emails Aug-Sep'!$N$5:$N$104,"No")&" emails sent 6 Aug – 30 Sep 2026 used 'Plug and Play Marketing Communications'." -> 32 of 97 emails sent 6 Aug – 30 Sep 2026 used 'Plug and Play Marketing Communications'.

Sheet Contacts
A1: Contacts
A2: Source: HubSpot contact counts and Settings › Account & Billing › Usage, 8 Oct 2026.
A4: Measure | B4: Contacts | C4: % of marketing contacts
A5: All contacts | B5: 1198117 | C5: –
A6: Marketing contacts (Marketing contact status = Marketing contact) | B6: 590458 | C6: 1
A7: Marketing contact tier | B7: 630000 | C7: –
A8: Marketing contacts with no marketing email open or click in last 12 months (never opened/clicked included) | B8: 508812 | C8: =B8/$B$6 -> 0.86172429
A9: Marketing contacts who never opened a marketing email | B9: 433657 | C9: =B9/$B$6 -> 0.73444174
A10: Marketing contacts with known open/click dates, both older than 12 months | B10: 29115 | C10: =B10/$B$6 -> 0.04930918
A11: Contacts who clicked a marketing email in last 12 months | B11: 20539 | C11: –
A12: Contacts who clicked a marketing email in last 6 months | B12: 12055 | C12: –
A13: Contacts with a bounce recorded (marketing emails bounced or hard bounce reason known) | B13: 76830 | C13: –
A14: Contacts unsubscribed from all email | B14: 10148 | C14: –
A15: Contacts scheduled to become non-marketing before 31 Oct 2026 | B15: 454 | C15: –
A16: Marketing contacts who opened or clicked in last 12 months | B16: =B6-B8 -> 81646 | C16: =B16/B6 -> 0.13827571
A17: Marketing contacts left before the tier limit (and % of tier used) | B17: =B7-B6 -> 39542 | C17: =B6/B7 -> 0.93723492
A19: Next marketing contact update: 31 Oct 2026. Last billing date: 19 Sep 2026.

Sheet Subscription Types
A1: Subscription types (95: 14 active, 81 archived)
A2: Source: Settings › Marketing › Email › Subscriptions, 8 Oct 2026. All on the default business unit.
A4: Name | B4: Description | C4: Status
A5: Fintech & AI Fund Insights | B5: This newsletter is where we'll track what's actually happening across our fund, including partnerships going live, portfolio wins, and the shifts we're watching in fintech and AI. | C5: Active
A6: Internal Plug and Play Communications | B6: Internal updates and announcements for Plug and Play teams | C6: Active
A7: One to One | B7: One to One emails | C7: Active
A8: Plug and Play APAC | B8: The latest news, event updates, and more about Plug and Play APAC in your inbox | C8: Active
A9: Plug and Play Brand and Retail team | B9: News, insights and events from Plug and Play Brand and Retail | C9: Active
A10: Plug and Play Events | B10: The latest event updates from Plug and Play in your inbox | C10: Active
A11: Plug and Play Foundation | B11: Latest updates and news from the Plug and Play Foundation | C11: Active
A12: Plug and Play Global Newsletter | B12: The latest news, event updates, and more about Plug and Play in your inbox | C12: Active
A13: Plug and Play Information & Services | B13: Information about programs and services from Plug and Play | C13: Active
A14: Plug and Play Japan | B14: The latest news, event updates, and more about Plug and Play Japan in your inbox | C14: Active
A15: Plug and Play Los Angeles | B15: Los Angeles | C15: Active
... A99: University Pitch Session Americas | B99: 30 startups from different universities pitch every Wednesday | C99: Archived
A101: Subscription settings
A102: Unsubscribe feedback survey | B102: OFF
A103: Resubscription email | B103: OFF
A104: Don't send to unengaged contacts | B104: ON
A105: Compliance BCC | B105: OFF
A106: Active subscription types (count) | B106: =COUNTIF(C5:C99,"Active") -> 14
A107: Archived subscription types (count) | B107: =COUNTIF(C5:C99,"Archived") -> 81

Sheet Workflows
A1: Workflows with a 'Send email' action (309)
A2: Source: Automation › Workflows, 8 Oct 2026.
A4: Workflow | B4: Status | C4: Currently enrolled | D4: Last updated | E4: ON and last updated before 2024
A5: LNS - RFI - 2025 | B5: On | C5: 4742 | D5: 2026-09-03 | E5: =IF(AND(B5="On",D5<"2024-01-01"),"Yes","No") -> No
A6: IA - CDW - EAI - Report - The Ultimate AI Playbook | B6: On | C6: 12 | D6: 2026-03-09 | E6: =IF(AND(B6="On",D6<"2024-01-01"),"Yes","No") -> No
A7: GNL reactivation campaign | B7: On | C7: 7 | D7: 2026-04-09 | E7: =IF(AND(B7="On",D7<"2024-01-01"),"Yes","No") -> No
A8: IA - CDW - EGY - Report - Energizing AI: A Deep Dive Into the Data Center Energy Value Chain | B8: On | C8: 0 | D8: 2026-09-23 | E8: =IF(AND(B8="On",D8<"2024-01-01"),"Yes","No") -> No
A9: IA - CDW - AI Survey Report | B9: On | C9: 0 | D9: 2026-09-22 | E9: =IF(AND(B9="On",D9<"2024-01-01"),"Yes","No") -> No
A10: Send a follow-up email after form submission | B10: On | C10: 0 | D10: 2026-09-09 | E10: =IF(AND(B10="On",D10<"2024-01-01"),"Yes","No") -> No
A11: JAP \| JTP_Japan Summit Inquiry | B11: On | C11: 0 | D11: 2026-07-29 | E11: =IF(AND(B11="On",D11<"2024-01-01"),"Yes","No") -> No
A12: IA - CDW - EGY - Report - Secure Systems: Building Resilient Energy Infrastructure | B12: On | C12: 0 | D12: 2026-07-09 | E12: =IF(AND(B12="On",D12<"2024-01-01"),"Yes","No") -> No
A13: IA - CDW - Innovation Assessment Report | B13: On | C13: 0 | D13: 2026-07-06 | E13: =IF(AND(B13="On",D13<"2024-01-01"),"Yes","No") -> No
A14: IA - CDW - EAI - Report - The AI-Enabled Waste Recovery Opportunity | B14: On | C14: 0 | D14: 2026-07-02 | E14: =IF(AND(B14="On",D14<"2024-01-01"),"Yes","No") -> No
A15: JAP \| JTP_Resource Download Thanks Mail_Trend Report | B15: On | C15: 0 | D15: 2026-06-16 | E15: =IF(AND(B15="On",D15<"2024-01-01"),"Yes","No") -> No
A16: JAP \| JTP_Resource Download Thanks Mail_Company Report | B16: On | C16: 0 | D16: 2026-06-16 | E16: =IF(AND(B16="On",D16<"2024-01-01"),"Yes","No") -> No
... A313: LNS_Lead Nurturing_Lead to SQL | B313: Off | C313: 0 | D313: 2022-02-15 | E313: =IF(AND(B313="On",D313<"2024-01-01"),"Yes","No") -> No
A315: Total | B315: =COUNTA(A5:A313) -> 309
A316: ON | B316: =COUNTIF(B5:B313,"On") -> 251
A317: OFF | B317: =COUNTIF(B5:B313,"Off") -> 58
A318: ON and last updated before 2024 | B318: =COUNTIF(E5:E313,"Yes") -> 65
A319: ON with 'COVID' in the name | B319: =COUNTIFS(A5:A313,"*COVID*",B5:B313,"On") -> 5

Sheet Teams
A1: HubSpot teams (62)
A2: Source: HubSpot teams list, 8 Oct 2026. None of the 1,042 emails sent 1 Oct 2025 – 30 Sep 2026 has a team assigned.
A4: Team | B4: Primary users | C4: Secondary users | D4: Parent team
A5: Abu Dhabi | B5: 3 | C5: 0
A6: AgTech | B6: 0 | C6: 0
A7: Alberta | B7: 3 | C7: 0
A8: Amsterdam | B8: 1 | C8: 0
A9: APAC | B9: 5 | C9: 0
A10: Arizona | B10: 4 | C10: 1 | D10: Supply Chain
A11: Barcelona | B11: 2 | C11: 1
A12: Basel | B12: 0 | C12: 0
A13: Borja's team - VLC | B13: 6 | C13: 0
A14: Brazil | B14: 0 | C14: 0
A15: Building Ops SV | B15: 0 | C15: 2
A16: Cleveland Team | B16: 2 | C16: 0
A17: Corporate Overall | B17: 2 | C17: 0
A18: Egypt | B18: 1 | C18: 0
A19: EMEA Fund | B19: 3 | C19: 1
A20: Energy | B20: 2 | C20: 1
A21: Fintech | B21: 6 | C21: 0
A22: Food | B22: 2 | C22: 0
... A31: Italy | B31: 3 | C31: 0
A32: ITALY BD | B32: 2 | C32: 0 | D32: Italy
A33: Japan | B33: 32 | C33: 0
A34: Kazakhstan | B34: 1 | C34: 0
A35: LA | B35: 2 | C35: 1
A36: LATAM | B36: 0 | C36: 0
A37: London | B37: 3 | C37: 0
A38: Maritime | B38: 0 | C38: 0
A39: Marketing | B39: 15 | C39: 3
A40: Materials | B40: 1 | C40: 0
A41: Media | B41: 0 | C41: 1
A42: Media & Advertising | B42: 0 | C42: 1 | D42: LA
A43: Mobility/IoT | B43: 8 | C43: 0
A44: munich | B44: 1 | C44: 0
A45: Nordics | B45: 0 | C45: 0
A46: Operations | B46: 3 | C46: 0
A47: Paris | B47: 0 | C47: 0
A48: Real Estate | B48: 2 | C48: 0
A49: Retail | B49: 4 | C49: 0
...

Sheet Emails Aug-Sep
A1: Sent emails, 6 Aug – 30 Sep 2026 (latest 100 records)
A2: Source: HubSpot › Marketing › Email › Manage, 8 Oct 2026. Rows marked Duplicate = Yes have identical stats to another row and are excluded from totals.
A4: Email name | B4: Send date | C4: From name | D4: Subscription type | E4: Newsletter | F4: Delivered | G4: Open rate | H4: Click rate | I4: Clicks (calc.) | J4: Unsubscribes | K4: Unsub rate | L4: Bounces (hard + soft) | M4: Bounce rate | N4: Duplicate
A5: 2026 travel nov summit outreach (rest) | B5: 2026-09-30 | C5: Brandon Lee | D5: Plug and Play Travel and Hospitality Silicon Valley | F5: 576 | G5: 0.311 | H5: 0.028 | I5: =ROUND(F5*H5,0) -> 16 | J5: 3 | K5: =IF(F5=0,0,J5/F5) -> 0.0052083333 | L5: 32 | M5: =IF(F5+L5=0,0,L5/(F5+L5)) -> 0.052631579 | N5: No
A6: September_Internal_Newsletter | B6: 2026-09-30 | C6: Sanam Amidi | D6: Internal Plug and Play Communications | E6: Internal Newsletter | F6: 618 | G6: 0.12 | H6: 0.06 | I6: =ROUND(F6*H6,0) -> 37 | J6: 0 | K6: =IF(F6=0,0,J6/F6) -> 0 | L6: 1 | M6: =IF(F6+L6=0,0,L6/(F6+L6)) -> 0.0016155089 | N6: No
A7: Physical AI | B7: 2026-09-30 | C7: Rick Hernandez | D7: Plug and Play Events | F7: 124 | G7: 0.452 | H7: 0.008 | I7: =ROUND(F7*H7,0) -> 1 | J7: 0 | K7: =IF(F7=0,0,J7/F7) -> 0 | L7: 0 | M7: =IF(F7+L7=0,0,L7/(F7+L7)) -> 0 | N7: No
A8: UK September 2026 Newsletter | B8: 2026-09-30 | C8: Kieran Borrett | D8: Plug and Play Marketing Communications | E8: UK Newsletter | F8: 6415 | G8: 0.261 | H8: 0.009 | I8: =ROUND(F8*H8,0) -> 58 | J8: 56 | K8: =IF(F8=0,0,J8/F8) -> 0.0087295401 | L8: 38 | M8: =IF(F8+L8=0,0,L8/(F8+L8)) -> 0.0058887339 | N8: No
A9: JAP_Newsletter_Sept - 2026 - 30 | B9: 2026-09-30 | C9: Plug and Play Japan | D9: Plug and Play Japan | E9: Japan Newsletter | F9: 1108 | G9: 0.428 | H9: 0.057 | I9: =ROUND(F9*H9,0) -> 63 | J9: 0 | K9: =IF(F9=0,0,J9/F9) -> 0 | L9: 1 | M9: =IF(F9+L9=0,0,L9/(F9+L9)) -> 0.00090171326 | N9: No
A10: Tirana Expo Invitation (2) 2026 | B10: 2026-09-30 | C10: Plug and Play Tirana | D10: Plug and Play Events | F10: 958 | G10: 0.31 | H10: 0.082 | I10: =ROUND(F10*H10,0) -> 79 | J10: 4 | K10: =IF(F10=0,0,J10/F10) -> 0.0041753653 | L10: 16 | M10: =IF(F10+L10=0,0,L10/(F10+L10)) -> 0.016427105 | N10: No
A11: October Events | B11: 2026-09-30 | C11: Rick Hernandez | D11: Plug and Play Events | F11: 124 | G11: 0.653 | H11: 0.016 | I11: =ROUND(F11*H11,0) -> 2 | J11: 0 | K11: =IF(F11=0,0,J11/F11) -> 0 | L11: 0 | M11: =IF(F11+L11=0,0,L11/(F11+L11)) -> 0 | N11: No
A12: GNL_September 2026 | B12: 2026-09-29 | C12: Jacky from Plug and Play | D12: Plug and Play Global Newsletter | E12: Global Newsletter (GNL) | F12: 7029 | G12: 0.178 | H12: 0.03 | I12: =ROUND(F12*H12,0) -> 211 | J12: 29 | K12: =IF(F12=0,0,J12/F12) -> 0.0041257647 | L12: 34 | M12: =IF(F12+L12=0,0,L12/(F12+L12)) -> 0.0048138185 | N12: No
A13: TEXAS September Newsletter | B13: 2026-09-29 | C13: Francis from Plug and Play | D13: Plug and Play Marketing Communications | E13: Texas Newsletter | F13: 4698 | G13: 0.245 | H13: 0.026 | I13: =ROUND(F13*H13,0) -> 122 | J13: 28 | K13: =IF(F13=0,0,J13/F13) -> 0.005959983 | L13: 38 | M13: =IF(F13+L13=0,0,L13/(F13+L13)) -> 0.0080236486 | N13: No
A14: BRAM Newsletter #2 - RetailClub Notes/ September 2026 | B14: 2026-09-29 | C14: Plug and Play Brand and Retail | D14: Plug and Play Brand and Retail team | E14: Brand & Retail (BRAM) Newsletter | F14: 114 | G14: 0.254 | H14: 0.026 | I14: =ROUND(F14*H14,0) -> 3 | J14: 0 | K14: =IF(F14=0,0,J14/F14) -> 0 | L14: 0 | M14: =IF(F14+L14=0,0,L14/(F14+L14)) -> 0 | N14: No
A15: 🚀 Plug and Play Cyprus_Expo News | B15: 2026-09-29 | C15: Victoria from Plug and Play Cyprus | D15: Plug and Play Marketing Communications | F15: 3663 | G15: 0.292 | H15: 0.016 | I15: =ROUND(F15*H15,0) -> 59 | J15: 33 | K15: =IF(F15=0,0,J15/F15) -> 0.009009009 | L15: 65 | M15: =IF(F15+L15=0,0,L15/(F15+L15)) -> 0.017435622 | N15: No
A16: THF Launch_General (registered) (Sept 28) | B16: 2026-09-28 | C16: Plug and Play Finland | D16: Plug and Play Events | F16: 79 | G16: 0.544 | H16: 0 | I16: =ROUND(F16*H16,0) -> 0 | J16: 0 | K16: =IF(F16=0,0,J16/F16) -> 0 | L16: 0 | M16: =IF(F16+L16=0,0,L16/(F16+L16)) -> 0 | N16: No
A17: Live Pitch Feedback Event: Mobility & Advanced Hardware | B17: 2026-09-25 | C17: Rick Hernandez | D17: Plug and Play Events | F17: 124 | G17: 0.556 | H17: 0.065 | I17: =ROUND(F17*H17,0) -> 8 | J17: 0 | K17: =IF(F17=0,0,J17/F17) -> 0 | L17: 0 | M17: =IF(F17+L17=0,0,L17/(F17+L17)) -> 0 | N17: No
A18: New email | B18: 2026-09-24 | C18: roza amrollah | D18: Plug and Play Events | F18: 70 | G18: 0.486 | H18: 0.043 | I18: =ROUND(F18*H18,0) -> 3 | J18: 0 | K18: =IF(F18=0,0,J18/F18) -> 0 | L18: 0 | M18: =IF(F18+L18=0,0,L18/(F18+L18)) -> 0 | N18: No
A19: Summit for Tenants | B19: 2026-09-24 | C19: Rick Hernandez | D19: Plug and Play Events | F19: 125 | G19: 0.664 | H19: 0.192 | I19: =ROUND(F19*H19,0) -> 24 | J19: 0 | K19: =IF(F19=0,0,J19/F19) -> 0 | L19: 0 | M19: =IF(F19+L19=0,0,L19/(F19+L19)) -> 0 | N19: No
A20: Fintech & AI Insights - Edition 2 - September 23, 2026 | B20: 2026-09-23 | C20: Brooke Ballinger | D20: Fintech & AI Fund Insights | E20: Fintech & AI Fund Insights | F20: 8611 | G20: 0.359 | H20: 0.007 | I20: =ROUND(F20*H20,0) -> 60 | J20: 122 | K20: =IF(F20=0,0,J20/F20) -> 0.014167925 | L20: 113 | M20: =IF(F20+L20=0,0,L20/(F20+L20)) -> 0.012952774 | N20: No
A21: ME Innovation Day, Email 2 | B21: 2026-09-23 | C21: Ava Milana | D21: Plug and Play Marketing Communications | F21: 4295 | G21: 0.276 | H21: 0.02 | I21: =ROUND(F21*H21,0) -> 86 | J21: 26 | K21: =IF(F21=0,0,J21/F21) -> 0.0060535506 | L21: 44 | M21: =IF(F21+L21=0,0,L21/(F21+L21)) -> 0.010140585 | N21: No
A22: Alignment 2026 | B22: 2026-09-23 | C22: Rick Hernandez | D22: Plug and Play Events | F22: 126 | G22: 0.5 | H22: 0.056 | I22: =ROUND(F22*H22,0) -> 7 | J22: 0 | K22: =IF(F22=0,0,J22/F22) -> 0 | L22: 0 | M22: =IF(F22+L22=0,0,L22/(F22+L22)) -> 0 | N22: No
A23: APAC_Newsletter_September_2026 | B23: 2026-09-23 | C23: Plug and Play APAC | D23: Plug and Play APAC | E23: APAC Newsletter | F23: 2789 | G23: 0.321 | H23: 0.034 | I23: =ROUND(F23*H23,0) -> 95 | J23: 10 | K23: =IF(F23=0,0,J23/F23) -> 0.0035855145 | L23: 17 | M23: =IF(F23+L23=0,0,L23/(F23+L23)) -> 0.0060584462 | N23: No
A24: THF Launch_General (registered) (Sept 22) | B24: 2026-09-22 | C24: Plug and Play Finland | D24: Plug and Play Events | F24: 79 | G24: 0.544 | H24: 0.215 | I24: =ROUND(F24*H24,0) -> 17 | J24: 0 | K24: =IF(F24=0,0,J24/F24) -> 0 | L24: 0 | M24: =IF(F24+L24=0,0,L24/(F24+L24)) -> 0 | N24: No
A25: SMB Tech Connect | B25: 2026-09-22 | C25: Rick Hernandez | D25: Plug and Play Events | F25: 126 | G25: 0.563 | H25: 0.016 | I25: =ROUND(F25*H25,0) -> 2 | J25: 0 | K25: =IF(F25=0,0,J25/F25) -> 0 | L25: 0 | M25: =IF(F25+L25=0,0,L25/(F25+L25)) -> 0 | N25: No
A26: Indiana Medtech + Lifetech Newsletter September 2026 | B26: 2026-09-18 | C26: Plug and Play Indiana | D26: Plug and Play Marketing Communications | E26: Indiana Medtech + Lifetech Newsletter | F26: 1430 | G26: 0.414 | H26: 0.013 | I26: =ROUND(F26*H26,0) -> 19 | J26: 8 | K26: =IF(F26=0,0,J26/F26) -> 0.0055944056 | L26: 10 | M26: =IF(F26+L26=0,0,L26/(F26+L26)) -> 0.0069444444 | N26: No
A27: Indiana Medtech + Lifetech Newsletter September 2026 | B27: 2026-09-18 | C27: Plug and Play Indiana | D27: Plug and Play Marketing Communications | E27: Indiana Medtech + Lifetech Newsletter | F27: 1430 | G27: 0.414 | H27: 0.013 | I27: =ROUND(F27*H27,0) -> 19 | J27: 8 | K27: =IF(F27=0,0,J27/F27) -> 0.0055944056 | L27: 10 | M27: =IF(F27+L27=0,0,L27/(F27+L27)) -> 0.0069444444 | N27: Yes
A28: JTP | JAP_Sansan List_Consent Mail_20260909 | B28: 2026-09-18 | C28: Plug and Play Japan | D28: Plug and Play Japan | F28: 38385 | G28: 0.229 | H28: 0.003 | I28: =ROUND(F28*H28,0) -> 115 | J28: 735 | K28: =IF(F28=0,0,J28/F28) -> 0.019148105 | L28: 3576 | M28: =IF(F28+L28=0,0,L28/(F28+L28)) -> 0.085221992 | N28: No
A29: 2026 travel nov summit outreach | B29: 2026-09-18 | C29: Brandon Lee | D29: Plug and Play Travel and Hospitality Silicon Valley | F29: 1545 | G29: 0.35 | H29: 0.015 | I29: =ROUND(F29*H29,0) -> 23 | J29: 25 | K29: =IF(F29=0,0,J29/F29) -> 0.01618123 | L29: 48 | M29: =IF(F29+L29=0,0,L29/(F29+L29)) -> 0.030131827 | N29: No
A30: Indiana Lifetech & Medtech Alumni - Invitation to SV Summit November 2026 | B30: 2026-09-17 | C30: Eileen Alberding | D30: Plug and Play Events | F30: 108 | G30: 0.472 | H30: 0.028 | I30: =ROUND(F30*H30,0) -> 3 | J30: 0 | K30: =IF(F30=0,0,J30/F30) -> 0 | L30: 1 | M30: =IF(F30+L30=0,0,L30/(F30+L30)) -> 0.0091743119 | N30: No
A31: Indiana Lifetech & Medtech Mentors - Invitation to SV Summit November 2026 (Clone) | B31: 2026-09-17 | C31: Eileen Alberding | D31: Plug and Play Events | F31: 72 | G31: 0.653 | H31: 0.208 | I31: =ROUND(F31*H31,0) -> 15 | J31: 0 | K31: =IF(F31=0,0,J31/F31) -> 0 | L31: 0 | M31: =IF(F31+L31=0,0,L31/(F31+L31)) -> 0 | N31: No
A32: ITA26_Newsletter September | B32: 2026-09-17 | C32: Tommaso Maschera | D32: Plug and Play Marketing Communications | E32: Italy Newsletter | F32: 7259 | G32: 0.263 | H32: 0.01 | I32: =ROUND(F32*H32,0) -> 73 | J32: 62 | K32: =IF(F32=0,0,J32/F32) -> 0.0085411214 | L32: 100 | M32: =IF(F32+L32=0,0,L32/(F32+L32)) -> 0.013588803 | N32: No
A33: JAP_Newsletter - Sept - 2026 - 16 | B33: 2026-09-16 | C33: Plug and Play Japan | D33: Plug and Play Japan | E33: Japan Newsletter | F33: 887 | G33: 0.263 | H33: 0.061 | I33: =ROUND(F33*H33,0) -> 54 | J33: 2 | K33: =IF(F33=0,0,J33/F33) -> 0.0022547914 | L33: 1 | M33: =IF(F33+L33=0,0,L33/(F33+L33)) -> 0.0011261261 | N33: No
A34: KOCCA SG Biz Matching -1 | B34: 2026-09-16 | C34: Tae Rin Ha | D34: Plug and Play APAC | F34: 44 | G34: 0.455 | H34: 0.114 | I34: =ROUND(F34*H34,0) -> 5 | J34: 0 | K34: =IF(F34=0,0,J34/F34) -> 0 | L34: 0 | M34: =IF(F34+L34=0,0,L34/(F34+L34)) -> 0 | N34: No
A35: THF_Selected (FORM - follow up) | B35: 2026-09-16 | C35: Plug and Play Finland | D35: Plug and Play Marketing Communications | F35: 9 | G35: 0.889 | H35: 0.556 | I35: =ROUND(F35*H35,0) -> 5 | J35: 0 | K35: =IF(F35=0,0,J35/F35) -> 0 | L35: 0 | M35: =IF(F35+L35=0,0,L35/(F35+L35)) -> 0 | N35: No
A36: THF Launch_General (NOT registered) (Sept 15) | B36: 2026-09-15 | C36: Plug and Play Finland | D36: Plug and Play Events | F36: 90 | G36: 0.333 | H36: 0.089 | I36: =ROUND(F36*H36,0) -> 8 | J36: 0 | K36: =IF(F36=0,0,J36/F36) -> 0 | L36: 1 | M36: =IF(F36+L36=0,0,L36/(F36+L36)) -> 0.010989011 | N36: No
A37: THF Launch_General (registered) (Sept 15) | B37: 2026-09-15 | C37: Plug and Play Finland | D37: Plug and Play Events | F37: 73 | G37: 0.466 | H37: 0.11 | I37: =ROUND(F37*H37,0) -> 8 | J37: 0 | K37: =IF(F37=0,0,J37/F37) -> 0 | L37: 0 | M37: =IF(F37+L37=0,0,L37/(F37+L37)) -> 0 | N37: No
A38: THF_Selected (FORM) | B38: 2026-09-15 | C38: Plug and Play Finland | D38: Plug and Play Marketing Communications | F38: 9 | G38: 0.889 | H38: 0.778 | I38: =ROUND(F38*H38,0) -> 7 | J38: 0 | K38: =IF(F38=0,0,J38/F38) -> 0 | L38: 0 | M38: =IF(F38+L38=0,0,L38/(F38+L38)) -> 0 | N38: No
A39: Reminder: Founders Lunch | B39: 2026-09-15 | C39: Rick Hernandez | D39: Plug and Play Events | F39: 123 | G39: 0.504 | H39: 0.057 | I39: =ROUND(F39*H39,0) -> 7 | J39: 0 | K39: =IF(F39=0,0,J39/F39) -> 0 | L39: 0 | M39: =IF(F39+L39=0,0,L39/(F39+L39)) -> 0 | N39: No
A40: Shamrock Foods - Monthly Signal August 31 (v1) | B40: 2026-09-14 | C40: Plug and Play Supply Chain | D40: Plug and Play Marketing Communications | E40: Shamrock Foods Monthly Signal | F40: 7 | G40: 0.857 | H40: 0 | I40: =ROUND(F40*H40,0) -> 0 | J40: 0 | K40: =IF(F40=0,0,J40/F40) -> 0 | L40: 0 | M40: =IF(F40+L40=0,0,L40/(F40+L40)) -> 0 | N40: No
A41: Selection Day & Batch Kickoff Thank you email | General Mills | B41: 2026-09-14 | C41: Tabitha Mills | D41: Plug and Play Global Newsletter | F41: 177 | G41: 0.508 | H41: 0.186 | I41: =ROUND(F41*H41,0) -> 33 | J41: 0 | K41: =IF(F41=0,0,J41/F41) -> 0 | L41: 1 | M41: =IF(F41+L41=0,0,L41/(F41+L41)) -> 0.0056179775 | N41: No
...

Sheet Sources
A1: Sources and definitions
A3: Data pulled | B3: 8 Oct 2026, read-only, HubSpot portal 3340630. Nothing in HubSpot was changed.
A4: Analyze export | B4: Marketing › Email › Analyze, 1 Oct 2025 – 30 Sep 2026, compared with previous 365 days.
A5: Health tab | B5: Marketing › Email › Health. Last 30 days = 5 Sep – 5 Oct 2026. Benchmarks are HubSpot's.
A6: Emails | B6: Latest 100 email records sent (6 Aug – 30 Sep 2026) out of 1,042 sent 1 Oct 2025 – 30 Sep 2026. 3 duplicate records excluded. Workflow (automated) emails not included.
A7: Click rate | B7: Unique clicks ÷ delivered.
A8: Unsub rate | B8: Unsubscribes ÷ delivered.
A9: Bounce rate (per email) | B9: All bounces (hard + soft) ÷ (delivered + bounces). Account-level bounce figures are hard bounces only.
A10: Newsletter | B10: Recurring newsletters grouped by email name (e.g. 'UK August 2026 Newsletter' and 'UK September 2026 Newsletter' = UK Newsletter).
A11: Contacts | B11: Contact counts from HubSpot contact search; marketing contacts and tier from Settings › Account & Billing › Usage.
